2024-03-13 09:57:24,391 - ERROR - Table name not found in setup file: setup_step7.json
2024-03-13 10:09:25,145 - ERROR - main_script_snap7_start: Table name not found in setup file: setup_step7.json
2024-03-13 10:11:08,856 - ERROR - main_script_snap7_start at line 84: Table name not found in setup file: setup_step7.json
2024-03-13 10:18:50,683 - ERROR - b'CLI : Cannot change this param now'
2024-03-13 10:18:50,683 - ERROR - Connect snap7 client error: b'CLI : Cannot change this param now'
Traceback (most recent call last):
  File "c:\Users\STM\Desktop\Praktik_Eksamensprojekt\Datalogging_Statistics_Project-SystemTM\Snap7_Functions.py", line 18, in connect_snap7_client
    client.connect(ip_address, rack, slot, tcpport)
  File "C:\Users\STM\AppData\Local\Programs\Python\Python312\Lib\site-packages\snap7\client\__init__.py", line 23, in f
    code = func(*args, **kw)
           ^^^^^^^^^^^^^^^^^
  File "C:\Users\STM\AppData\Local\Programs\Python\Python312\Lib\site-packages\snap7\client\__init__.py", line 192, in connect
    self.set_param(RemotePort, tcpport)
  File "C:\Users\STM\AppData\Local\Programs\Python\Python312\Lib\site-packages\snap7\client\__init__.py", line 24, in f
    check_error(code, context="client")
  File "C:\Users\STM\AppData\Local\Programs\Python\Python312\Lib\site-packages\snap7\common.py", line 89, in check_error
    raise RuntimeError(error)
RuntimeError: b'CLI : Cannot change this param now'
2024-03-13 10:18:50,697 - ERROR - Write data dbresult error: 'NoneType' object has no attribute 'db_write'
Traceback (most recent call last):
  File "c:\Users\STM\Desktop\Praktik_Eksamensprojekt\Datalogging_Statistics_Project-SystemTM\Snap7_Functions.py", line 134, in write_data_dbresult
    client.db_write(plc.get("dbresult db number"), plc.get('dbresult data index'), bytearray_to_write)
    ^^^^^^^^^^^^^^^
AttributeError: 'NoneType' object has no attribute 'db_write'
2024-03-13 10:19:00,685 - ERROR - b'CLI : Cannot change this param now'
2024-03-13 10:19:00,685 - ERROR - Connect snap7 client error: b'CLI : Cannot change this param now'
Traceback (most recent call last):
  File "c:\Users\STM\Desktop\Praktik_Eksamensprojekt\Datalogging_Statistics_Project-SystemTM\Snap7_Functions.py", line 18, in connect_snap7_client
    client.connect(ip_address, rack, slot, tcpport)
  File "C:\Users\STM\AppData\Local\Programs\Python\Python312\Lib\site-packages\snap7\client\__init__.py", line 23, in f
    code = func(*args, **kw)
           ^^^^^^^^^^^^^^^^^
  File "C:\Users\STM\AppData\Local\Programs\Python\Python312\Lib\site-packages\snap7\client\__init__.py", line 192, in connect
    self.set_param(RemotePort, tcpport)
  File "C:\Users\STM\AppData\Local\Programs\Python\Python312\Lib\site-packages\snap7\client\__init__.py", line 24, in f
    check_error(code, context="client")
  File "C:\Users\STM\AppData\Local\Programs\Python\Python312\Lib\site-packages\snap7\common.py", line 89, in check_error
    raise RuntimeError(error)
RuntimeError: b'CLI : Cannot change this param now'
2024-03-13 10:19:00,686 - ERROR - Write data dbresult error: 'NoneType' object has no attribute 'db_write'
Traceback (most recent call last):
  File "c:\Users\STM\Desktop\Praktik_Eksamensprojekt\Datalogging_Statistics_Project-SystemTM\Snap7_Functions.py", line 134, in write_data_dbresult
    client.db_write(plc.get("dbresult db number"), plc.get('dbresult data index'), bytearray_to_write)
    ^^^^^^^^^^^^^^^
AttributeError: 'NoneType' object has no attribute 'db_write'
2024-03-13 11:31:09,655 - ERROR - Setup file keys changed error: 'NoneType' object has no attribute 'values'
Traceback (most recent call last):
  File "c:\Users\STM\Desktop\Praktik_Eksamensprojekt\Datalogging_Statistics_Project-SystemTM\json_functions.py", line 113, in setup_file_keys_changed
    for plc_setup in previous_setup_file.values():
                     ^^^^^^^^^^^^^^^^^^^^^^^^^^
AttributeError: 'NoneType' object has no attribute 'values'
2024-03-18 10:32:20,128 - ERROR - Get seconds in range error: 'str' object has no attribute 'getSeconds'
Traceback (most recent call last):
  File "c:\Users\STM\Desktop\Praktik_Eksamensprojekt\Datalogging_Statistics_Project-SystemTM\SQLiteRead.py", line 277, in get_seconds_in_range
    print(ts.getSeconds())
          ^^^^^^^^^^^^^
AttributeError: 'str' object has no attribute 'getSeconds'
2024-03-18 10:33:03,920 - ERROR - Get seconds in range error: 'str' object has no attribute 'getSeconds'
Traceback (most recent call last):
  File "c:\Users\STM\Desktop\Praktik_Eksamensprojekt\Datalogging_Statistics_Project-SystemTM\SQLiteRead.py", line 279, in get_seconds_in_range
    print(ts.getSeconds())
          ^^^^^^^^^^^^^
AttributeError: 'str' object has no attribute 'getSeconds'
2024-03-18 10:50:58,615 - ERROR - Get seconds in range error: cannot access local variable 'time_delta_seconds' where it is not associated with a value
Traceback (most recent call last):
  File "c:\Users\STM\Desktop\Praktik_Eksamensprojekt\Datalogging_Statistics_Project-SystemTM\SQLiteRead.py", line 279, in get_seconds_in_range
    time_delta_seconds = time_delta_seconds.total_seconds()
                         ^^^^^^^^^^^^^^^^^^
UnboundLocalError: cannot access local variable 'time_delta_seconds' where it is not associated with a value
2024-03-18 10:50:58,615 - ERROR - Write data dbresult error: 'NoneType' object has no attribute 'to_bytes'
Traceback (most recent call last):
  File "c:\Users\STM\Desktop\Praktik_Eksamensprojekt\Datalogging_Statistics_Project-SystemTM\Snap7_Functions.py", line 135, in write_data_dbresult
    spanbyte_to_write = time_sec.to_bytes(4, byteorder='big')
                 ^^^^^^^^^^^^^^^^^
AttributeError: 'NoneType' object has no attribute 'to_bytes'
2024-03-18 10:51:15,326 - ERROR - Write data dbresult error: 'float' object has no attribute 'to_bytes'
Traceback (most recent call last):
  File "c:\Users\STM\Desktop\Praktik_Eksamensprojekt\Datalogging_Statistics_Project-SystemTM\Snap7_Functions.py", line 135, in write_data_dbresult
    spanbyte_to_write = time_sec.to_bytes(4, byteorder='big')
                 ^^^^^^^^^^^^^^^^^
AttributeError: 'float' object has no attribute 'to_bytes'
2024-03-18 10:51:50,974 - ERROR - b' ISO : Datasize passed to send/recv buffer is invalid'
2024-03-18 10:51:50,975 - ERROR - Write data dbresult error: b' ISO : Datasize passed to send/recv buffer is invalid'
Traceback (most recent call last):
  File "c:\Users\STM\Desktop\Praktik_Eksamensprojekt\Datalogging_Statistics_Project-SystemTM\Snap7_Functions.py", line 140, in write_data_dbresult
    client.db_write(plc.get("dbresult db number"), plc.get('dbresult data index'), bytearray_to_write)
  File "C:\Users\STM\AppData\Local\Programs\Python\Python312\Lib\site-packages\snap7\client\__init__.py", line 24, in f
    check_error(code, context="client")
  File "C:\Users\STM\AppData\Local\Programs\Python\Python312\Lib\site-packages\snap7\common.py", line 89, in check_error
    raise RuntimeError(error)
RuntimeError: b' ISO : Datasize passed to send/recv buffer is invalid'
2024-03-18 10:53:22,174 - ERROR - b' ISO : An error occurred during send TCP : Connection timed out'
2024-03-18 10:53:22,174 - ERROR - Write data dbresult error: b' ISO : An error occurred during send TCP : Connection timed out'
Traceback (most recent call last):
  File "c:\Users\STM\Desktop\Praktik_Eksamensprojekt\Datalogging_Statistics_Project-SystemTM\Snap7_Functions.py", line 142, in write_data_dbresult
    client.db_write(plc.get("dbresult db number"), plc.get('dbresult data index'), bytearray_to_write)
  File "C:\Users\STM\AppData\Local\Programs\Python\Python312\Lib\site-packages\snap7\client\__init__.py", line 24, in f
    check_error(code, context="client")
  File "C:\Users\STM\AppData\Local\Programs\Python\Python312\Lib\site-packages\snap7\common.py", line 89, in check_error
    raise RuntimeError(error)
RuntimeError: b' ISO : An error occurred during send TCP : Connection timed out'
2024-03-18 10:53:33,175 - ERROR - b' ISO : An error occurred during send TCP : Connection timed out'
2024-03-18 10:53:33,175 - ERROR - Write data dbresult error: b' ISO : An error occurred during send TCP : Connection timed out'
Traceback (most recent call last):
  File "c:\Users\STM\Desktop\Praktik_Eksamensprojekt\Datalogging_Statistics_Project-SystemTM\Snap7_Functions.py", line 142, in write_data_dbresult
    client.db_write(plc.get("dbresult db number"), plc.get('dbresult data index'), bytearray_to_write)
  File "C:\Users\STM\AppData\Local\Programs\Python\Python312\Lib\site-packages\snap7\client\__init__.py", line 24, in f
    check_error(code, context="client")
  File "C:\Users\STM\AppData\Local\Programs\Python\Python312\Lib\site-packages\snap7\common.py", line 89, in check_error
    raise RuntimeError(error)
RuntimeError: b' ISO : An error occurred during send TCP : Connection timed out'
2024-03-18 10:59:00,082 - ERROR - b' ISO : An error occurred during send TCP : Connection timed out'
2024-03-18 10:59:00,083 - ERROR - Write data dbresult error: b' ISO : An error occurred during send TCP : Connection timed out'
Traceback (most recent call last):
  File "c:\Users\STM\Desktop\Praktik_Eksamensprojekt\Datalogging_Statistics_Project-SystemTM\Snap7_Functions.py", line 143, in write_data_dbresult
    client.db_write(plc.get("dbresult db number"), plc.get('dbresult data index'), bytearray_to_write)
  File "C:\Users\STM\AppData\Local\Programs\Python\Python312\Lib\site-packages\snap7\client\__init__.py", line 24, in f
    check_error(code, context="client")
  File "C:\Users\STM\AppData\Local\Programs\Python\Python312\Lib\site-packages\snap7\common.py", line 89, in check_error
    raise RuntimeError(error)
RuntimeError: b' ISO : An error occurred during send TCP : Connection timed out'
2024-03-18 10:59:33,658 - ERROR - b' ISO : Datasize passed to send/recv buffer is invalid'
2024-03-18 10:59:33,658 - ERROR - Write data dbresult error: b' ISO : Datasize passed to send/recv buffer is invalid'
Traceback (most recent call last):
  File "c:\Users\STM\Desktop\Praktik_Eksamensprojekt\Datalogging_Statistics_Project-SystemTM\Snap7_Functions.py", line 144, in write_data_dbresult
    client.db_write(plc.get("dbresult db number"), plc.get('dbresult data index'), bytearray_to_write)
  File "C:\Users\STM\AppData\Local\Programs\Python\Python312\Lib\site-packages\snap7\client\__init__.py", line 24, in f
    check_error(code, context="client")
  File "C:\Users\STM\AppData\Local\Programs\Python\Python312\Lib\site-packages\snap7\common.py", line 89, in check_error
    raise RuntimeError(error)
RuntimeError: b' ISO : Datasize passed to send/recv buffer is invalid'
2024-03-18 11:04:10,576 - ERROR - b' ISO : Datasize passed to send/recv buffer is invalid'
2024-03-18 11:04:10,576 - ERROR - Write data dbresult error: b' ISO : Datasize passed to send/recv buffer is invalid'
Traceback (most recent call last):
  File "c:\Users\STM\Desktop\Praktik_Eksamensprojekt\Datalogging_Statistics_Project-SystemTM\Snap7_Functions.py", line 144, in write_data_dbresult
    client.db_write(plc.get("dbresult db number"), plc.get('dbresult data index'), bytearray_to_write)
  File "C:\Users\STM\AppData\Local\Programs\Python\Python312\Lib\site-packages\snap7\client\__init__.py", line 24, in f
    check_error(code, context="client")
  File "C:\Users\STM\AppData\Local\Programs\Python\Python312\Lib\site-packages\snap7\common.py", line 89, in check_error
    raise RuntimeError(error)
RuntimeError: b' ISO : Datasize passed to send/recv buffer is invalid'
2024-03-18 11:06:08,753 - ERROR - b' ISO : Datasize passed to send/recv buffer is invalid'
2024-03-18 11:06:08,754 - ERROR - Write data dbresult error: b' ISO : Datasize passed to send/recv buffer is invalid'
Traceback (most recent call last):
  File "c:\Users\STM\Desktop\Praktik_Eksamensprojekt\Datalogging_Statistics_Project-SystemTM\Snap7_Functions.py", line 142, in write_data_dbresult
    client.db_write(plc.get("dbresult db number"), plc.get('dbresult data index'), bytearray_to_write)
  File "C:\Users\STM\AppData\Local\Programs\Python\Python312\Lib\site-packages\snap7\client\__init__.py", line 24, in f
    check_error(code, context="client")
  File "C:\Users\STM\AppData\Local\Programs\Python\Python312\Lib\site-packages\snap7\common.py", line 89, in check_error
    raise RuntimeError(error)
RuntimeError: b' ISO : Datasize passed to send/recv buffer is invalid'
2024-03-18 11:07:22,535 - ERROR - b' ISO : An error occurred during send TCP : Connection timed out'
2024-03-18 11:07:22,536 - ERROR - Write data dbresult error: b' ISO : An error occurred during send TCP : Connection timed out'
Traceback (most recent call last):
  File "c:\Users\STM\Desktop\Praktik_Eksamensprojekt\Datalogging_Statistics_Project-SystemTM\Snap7_Functions.py", line 143, in write_data_dbresult
    client.db_write(plc.get("dbresult db number"), plc.get('dbresult data index'), bytearray_to_write)
  File "C:\Users\STM\AppData\Local\Programs\Python\Python312\Lib\site-packages\snap7\client\__init__.py", line 24, in f
    check_error(code, context="client")
  File "C:\Users\STM\AppData\Local\Programs\Python\Python312\Lib\site-packages\snap7\common.py", line 89, in check_error
    raise RuntimeError(error)
RuntimeError: b' ISO : An error occurred during send TCP : Connection timed out'
2024-03-18 11:11:27,482 - ERROR - b' ISO : Datasize passed to send/recv buffer is invalid'
2024-03-18 11:11:27,482 - ERROR - Write data dbresult error: b' ISO : Datasize passed to send/recv buffer is invalid'
Traceback (most recent call last):
  File "c:\Users\STM\Desktop\Praktik_Eksamensprojekt\Datalogging_Statistics_Project-SystemTM\Snap7_Functions.py", line 145, in write_data_dbresult
    client.db_write(plc.get("dbresult db number"), plc.get('dbresult data index'), bytearray_to_write)
  File "C:\Users\STM\AppData\Local\Programs\Python\Python312\Lib\site-packages\snap7\client\__init__.py", line 24, in f
    check_error(code, context="client")
  File "C:\Users\STM\AppData\Local\Programs\Python\Python312\Lib\site-packages\snap7\common.py", line 89, in check_error
    raise RuntimeError(error)
RuntimeError: b' ISO : Datasize passed to send/recv buffer is invalid'
2024-03-18 11:18:27,249 - ERROR - b' ISO : An error occurred during send TCP : Connection timed out'
2024-03-18 11:18:27,249 - ERROR - Write data dbresult error: b' ISO : An error occurred during send TCP : Connection timed out'
Traceback (most recent call last):
  File "c:\Users\STM\Desktop\Praktik_Eksamensprojekt\Datalogging_Statistics_Project-SystemTM\Snap7_Functions.py", line 145, in write_data_dbresult
    client.db_write(plc.get("dbresult db number"), plc.get('dbresult data index'), bytearray_to_write)
  File "C:\Users\STM\AppData\Local\Programs\Python\Python312\Lib\site-packages\snap7\client\__init__.py", line 24, in f
    check_error(code, context="client")
  File "C:\Users\STM\AppData\Local\Programs\Python\Python312\Lib\site-packages\snap7\common.py", line 89, in check_error
    raise RuntimeError(error)
RuntimeError: b' ISO : An error occurred during send TCP : Connection timed out'
2024-03-18 11:18:43,861 - ERROR - b' ISO : Datasize passed to send/recv buffer is invalid'
2024-03-18 11:18:43,862 - ERROR - Write data dbresult error: b' ISO : Datasize passed to send/recv buffer is invalid'
Traceback (most recent call last):
  File "c:\Users\STM\Desktop\Praktik_Eksamensprojekt\Datalogging_Statistics_Project-SystemTM\Snap7_Functions.py", line 145, in write_data_dbresult
    client.db_write(plc.get("dbresult db number"), plc.get('dbresult data index'), bytearray_to_write)
  File "C:\Users\STM\AppData\Local\Programs\Python\Python312\Lib\site-packages\snap7\client\__init__.py", line 24, in f
    check_error(code, context="client")
  File "C:\Users\STM\AppData\Local\Programs\Python\Python312\Lib\site-packages\snap7\common.py", line 89, in check_error
    raise RuntimeError(error)
RuntimeError: b' ISO : Datasize passed to send/recv buffer is invalid'
2024-03-18 11:20:08,806 - ERROR - b' ISO : Datasize passed to send/recv buffer is invalid'
2024-03-18 11:20:08,806 - ERROR - Write data dbresult error: b' ISO : Datasize passed to send/recv buffer is invalid'
Traceback (most recent call last):
  File "c:\Users\STM\Desktop\Praktik_Eksamensprojekt\Datalogging_Statistics_Project-SystemTM\Snap7_Functions.py", line 145, in write_data_dbresult
    client.db_write(plc.get("dbresult db number"), plc.get('dbresult data index'), bytearray_to_write)
  File "C:\Users\STM\AppData\Local\Programs\Python\Python312\Lib\site-packages\snap7\client\__init__.py", line 24, in f
    check_error(code, context="client")
  File "C:\Users\STM\AppData\Local\Programs\Python\Python312\Lib\site-packages\snap7\common.py", line 89, in check_error
    raise RuntimeError(error)
RuntimeError: b' ISO : Datasize passed to send/recv buffer is invalid'
2024-03-18 11:23:30,504 - ERROR - b' ISO : Datasize passed to send/recv buffer is invalid'
2024-03-18 11:23:30,505 - ERROR - Write data dbresult error: b' ISO : Datasize passed to send/recv buffer is invalid'
Traceback (most recent call last):
  File "c:\Users\STM\Desktop\Praktik_Eksamensprojekt\Datalogging_Statistics_Project-SystemTM\Snap7_Functions.py", line 146, in write_data_dbresult
    client.db_write(plc.get("dbresult db number"), plc.get('dbresult data index'), bytearray_to_write)
  File "C:\Users\STM\AppData\Local\Programs\Python\Python312\Lib\site-packages\snap7\client\__init__.py", line 24, in f
    check_error(code, context="client")
  File "C:\Users\STM\AppData\Local\Programs\Python\Python312\Lib\site-packages\snap7\common.py", line 89, in check_error
    raise RuntimeError(error)
RuntimeError: b' ISO : Datasize passed to send/recv buffer is invalid'
2024-03-18 11:28:18,348 - ERROR - b' ISO : Datasize passed to send/recv buffer is invalid'
2024-03-18 11:28:18,348 - ERROR - Write data dbresult error: b' ISO : Datasize passed to send/recv buffer is invalid'
Traceback (most recent call last):
  File "c:\Users\STM\Desktop\Praktik_Eksamensprojekt\Datalogging_Statistics_Project-SystemTM\Snap7_Functions.py", line 147, in write_data_dbresult
    client.db_write(plc.get("dbresult db number"), plc.get('dbresult data index'), bytearray_to_write)
  File "C:\Users\STM\AppData\Local\Programs\Python\Python312\Lib\site-packages\snap7\client\__init__.py", line 24, in f
    check_error(code, context="client")
  File "C:\Users\STM\AppData\Local\Programs\Python\Python312\Lib\site-packages\snap7\common.py", line 89, in check_error
    raise RuntimeError(error)
RuntimeError: b' ISO : Datasize passed to send/recv buffer is invalid'
2024-03-18 11:33:02,919 - ERROR - b' ISO : An error occurred during send TCP : Connection timed out'
2024-03-18 11:33:02,919 - ERROR - Write data dbresult error: b' ISO : An error occurred during send TCP : Connection timed out'
Traceback (most recent call last):
  File "c:\Users\STM\Desktop\Praktik_Eksamensprojekt\Datalogging_Statistics_Project-SystemTM\Snap7_Functions.py", line 147, in write_data_dbresult
    client.db_write(plc.get("dbresult db number"), plc.get('dbresult data index'), bytearray_to_write)
  File "C:\Users\STM\AppData\Local\Programs\Python\Python312\Lib\site-packages\snap7\client\__init__.py", line 24, in f
    check_error(code, context="client")
  File "C:\Users\STM\AppData\Local\Programs\Python\Python312\Lib\site-packages\snap7\common.py", line 89, in check_error
    raise RuntimeError(error)
RuntimeError: b' ISO : An error occurred during send TCP : Connection timed out'
2024-03-18 11:33:09,194 - ERROR - b' ISO : Datasize passed to send/recv buffer is invalid'
2024-03-18 11:33:09,195 - ERROR - Write data dbresult error: b' ISO : Datasize passed to send/recv buffer is invalid'
Traceback (most recent call last):
  File "c:\Users\STM\Desktop\Praktik_Eksamensprojekt\Datalogging_Statistics_Project-SystemTM\Snap7_Functions.py", line 147, in write_data_dbresult
    client.db_write(plc.get("dbresult db number"), plc.get('dbresult data index'), bytearray_to_write)
  File "C:\Users\STM\AppData\Local\Programs\Python\Python312\Lib\site-packages\snap7\client\__init__.py", line 24, in f
    check_error(code, context="client")
  File "C:\Users\STM\AppData\Local\Programs\Python\Python312\Lib\site-packages\snap7\common.py", line 89, in check_error
    raise RuntimeError(error)
RuntimeError: b' ISO : Datasize passed to send/recv buffer is invalid'
2024-03-18 15:18:32,251 - ERROR - Insert data into table error: cannot VACUUM from within a transaction
Traceback (most recent call last):
  File "c:\Users\STM\Desktop\Praktik_Eksamensprojekt\Datalogging_Statistics_Project-SystemTM\SQLiteWrite.py", line 24, in insert_data_into_table
    cursor. execute('VACUUM;')
sqlite3.OperationalError: cannot VACUUM from within a transaction
2024-03-18 15:18:42,483 - ERROR - Insert data into table error: cannot VACUUM from within a transaction
Traceback (most recent call last):
  File "c:\Users\STM\Desktop\Praktik_Eksamensprojekt\Datalogging_Statistics_Project-SystemTM\SQLiteWrite.py", line 24, in insert_data_into_table
    cursor. execute('VACUUM;')
sqlite3.OperationalError: cannot VACUUM from within a transaction
2024-03-18 15:18:56,013 - ERROR - Insert data into table error: database is locked
Traceback (most recent call last):
  File "c:\Users\STM\Desktop\Praktik_Eksamensprojekt\Datalogging_Statistics_Project-SystemTM\SQLiteWrite.py", line 23, in insert_data_into_table
    cursor.execute(insert_query, data)
sqlite3.OperationalError: database is locked
2024-03-18 15:19:03,871 - ERROR - Insert data into table error: database is locked
Traceback (most recent call last):
  File "c:\Users\STM\Desktop\Praktik_Eksamensprojekt\Datalogging_Statistics_Project-SystemTM\SQLiteWrite.py", line 23, in insert_data_into_table
    cursor.execute(insert_query, data)
sqlite3.OperationalError: database is locked
2024-03-18 15:19:10,944 - ERROR - Insert data into table error: database is locked
Traceback (most recent call last):
  File "c:\Users\STM\Desktop\Praktik_Eksamensprojekt\Datalogging_Statistics_Project-SystemTM\SQLiteWrite.py", line 23, in insert_data_into_table
    cursor.execute(insert_query, data)
sqlite3.OperationalError: database is locked
2024-03-18 15:19:18,430 - ERROR - Insert data into table error: database is locked
Traceback (most recent call last):
  File "c:\Users\STM\Desktop\Praktik_Eksamensprojekt\Datalogging_Statistics_Project-SystemTM\SQLiteWrite.py", line 23, in insert_data_into_table
    cursor.execute(insert_query, data)
sqlite3.OperationalError: database is locked
2024-03-18 15:19:26,669 - ERROR - Insert data into table error: database is locked
Traceback (most recent call last):
  File "c:\Users\STM\Desktop\Praktik_Eksamensprojekt\Datalogging_Statistics_Project-SystemTM\SQLiteWrite.py", line 23, in insert_data_into_table
    cursor.execute(insert_query, data)
sqlite3.OperationalError: database is locked
2024-03-18 15:19:35,731 - ERROR - Insert data into table error: database is locked
Traceback (most recent call last):
  File "c:\Users\STM\Desktop\Praktik_Eksamensprojekt\Datalogging_Statistics_Project-SystemTM\SQLiteWrite.py", line 23, in insert_data_into_table
    cursor.execute(insert_query, data)
sqlite3.OperationalError: database is locked
2024-03-18 15:19:45,689 - ERROR - Insert data into table error: database is locked
Traceback (most recent call last):
  File "c:\Users\STM\Desktop\Praktik_Eksamensprojekt\Datalogging_Statistics_Project-SystemTM\SQLiteWrite.py", line 23, in insert_data_into_table
    cursor.execute(insert_query, data)
sqlite3.OperationalError: database is locked
2024-03-18 15:19:56,658 - ERROR - Insert data into table error: database is locked
Traceback (most recent call last):
  File "c:\Users\STM\Desktop\Praktik_Eksamensprojekt\Datalogging_Statistics_Project-SystemTM\SQLiteWrite.py", line 23, in insert_data_into_table
    cursor.execute(insert_query, data)
sqlite3.OperationalError: database is locked
2024-03-18 15:33:54,826 - ERROR - manage database size error: unrecognized token: "{"
Traceback (most recent call last):
  File "c:\Users\STM\Desktop\Praktik_Eksamensprojekt\Datalogging_Statistics_Project-SystemTM\SQLiteWrite.py", line 184, in manage_db_size
    cursor.execute("DELETE FROM {'Test_Table'} ORDER BY TimeStamp DESC LIMIT 10")
sqlite3.OperationalError: unrecognized token: "{"
2024-03-18 15:34:10,237 - ERROR - manage database size error: near "ORDER": syntax error
Traceback (most recent call last):
  File "c:\Users\STM\Desktop\Praktik_Eksamensprojekt\Datalogging_Statistics_Project-SystemTM\SQLiteWrite.py", line 184, in manage_db_size
    cursor.execute("DELETE FROM 'Test_Table' ORDER BY TimeStamp DESC LIMIT 10")
sqlite3.OperationalError: near "ORDER": syntax error
2024-03-18 15:34:44,660 - ERROR - manage database size error: near "ORDER": syntax error
Traceback (most recent call last):
  File "c:\Users\STM\Desktop\Praktik_Eksamensprojekt\Datalogging_Statistics_Project-SystemTM\SQLiteWrite.py", line 184, in manage_db_size
    cursor.execute("DELETE FROM 'Test_Table' ORDER BY TimeStamp DESC LIMIT 10")
sqlite3.OperationalError: near "ORDER": syntax error
2024-03-18 15:35:04,419 - ERROR - manage database size error: near "ORDER": syntax error
Traceback (most recent call last):
  File "c:\Users\STM\Desktop\Praktik_Eksamensprojekt\Datalogging_Statistics_Project-SystemTM\SQLiteWrite.py", line 184, in manage_db_size
    cursor.execute("DELETE FROM Test_Table ORDER BY TimeStamp DESC LIMIT 10")
sqlite3.OperationalError: near "ORDER": syntax error
2024-03-19 07:47:35,340 - ERROR - Read setup file error: [Errno 2] No such file or directory: '1'
Traceback (most recent call last):
  File "c:\Users\STM\Desktop\Praktik_Eksamensprojekt\Datalogging_Statistics_Project-SystemTM\json_functions.py", line 7, in read_setup_file
    setup_file = open(f'{setup_file_name}')
                 ^^^^^^^^^^^^^^^^^^^^^^^^^^
FileNotFoundError: [Errno 2] No such file or directory: '1'
2024-03-19 07:47:35,345 - ERROR - Get plc from file error: 'NoneType' object has no attribute 'get'
Traceback (most recent call last):
  File "c:\Users\STM\Desktop\Praktik_Eksamensprojekt\Datalogging_Statistics_Project-SystemTM\json_functions.py", line 21, in get_plc_from_file
    plc1 = setup.get('PLC_1')
           ^^^^^^^^^
AttributeError: 'NoneType' object has no attribute 'get'
2024-03-19 07:47:35,345 - ERROR - Setup get sql column names from file error: 'NoneType' object has no attribute 'get'
Traceback (most recent call last):
  File "c:\Users\STM\Desktop\Praktik_Eksamensprojekt\Datalogging_Statistics_Project-SystemTM\json_functions.py", line 80, in setup_get_sql_column_names_from_file
    columns = plc1.get('column names')
              ^^^^^^^^
AttributeError: 'NoneType' object has no attribute 'get'
2024-03-19 07:47:35,345 - ERROR - Setup sql table from json error: 'NoneType' object is not iterable
Traceback (most recent call last):
  File "c:\Users\STM\Desktop\Praktik_Eksamensprojekt\Datalogging_Statistics_Project-SystemTM\SQLiteWrite.py", line 65, in setup_sql_table_from_json
    for I, column_dict in enumerate(json_setup_column_names):
                          ^^^^^^^^^^^^^^^^^^^^^^^^^^^^^^^^^^
TypeError: 'NoneType' object is not iterable
2024-03-19 07:47:38,285 - ERROR - Insert data into table error: table Test_Table has no column named Test_Data_Column_1
Traceback (most recent call last):
  File "c:\Users\STM\Desktop\Praktik_Eksamensprojekt\Datalogging_Statistics_Project-SystemTM\SQLiteWrite.py", line 23, in insert_data_into_table
    cursor.execute(insert_query, data)
sqlite3.OperationalError: table Test_Table has no column named Test_Data_Column_1
2024-03-19 07:47:38,285 - ERROR - Get seconds in range error: list index out of range
Traceback (most recent call last):
  File "c:\Users\STM\Desktop\Praktik_Eksamensprojekt\Datalogging_Statistics_Project-SystemTM\SQLiteRead.py", line 277, in get_seconds_in_range
    first_timestamp = datetime.strptime(timestamp_array[0]  , "%Y-%m-%d %H:%M:%S")
                                        ~~~~~~~~~~~~~~~^^^
IndexError: list index out of range
2024-03-19 07:47:38,290 - ERROR - Write data dbresult error: 'NoneType' object has no attribute 'to_bytes'
Traceback (most recent call last):
  File "c:\Users\STM\Desktop\Praktik_Eksamensprojekt\Datalogging_Statistics_Project-SystemTM\Snap7_Functions.py", line 131, in write_data_dbresult
    time_sec_byte_to_write = time_sec.to_bytes(4, byteorder='big')
                             ^^^^^^^^^^^^^^^^^
AttributeError: 'NoneType' object has no attribute 'to_bytes'
2024-03-19 07:47:46,034 - ERROR - Insert data into table error: table Test_Table has no column named Test_Data_Column_1
Traceback (most recent call last):
  File "c:\Users\STM\Desktop\Praktik_Eksamensprojekt\Datalogging_Statistics_Project-SystemTM\SQLiteWrite.py", line 23, in insert_data_into_table
    cursor.execute(insert_query, data)
sqlite3.OperationalError: table Test_Table has no column named Test_Data_Column_1
2024-03-19 07:47:46,034 - ERROR - Get seconds in range error: list index out of range
Traceback (most recent call last):
  File "c:\Users\STM\Desktop\Praktik_Eksamensprojekt\Datalogging_Statistics_Project-SystemTM\SQLiteRead.py", line 277, in get_seconds_in_range
    first_timestamp = datetime.strptime(timestamp_array[0]  , "%Y-%m-%d %H:%M:%S")
                                        ~~~~~~~~~~~~~~~^^^
IndexError: list index out of range
2024-03-19 07:47:46,035 - ERROR - Write data dbresult error: 'NoneType' object has no attribute 'to_bytes'
Traceback (most recent call last):
  File "c:\Users\STM\Desktop\Praktik_Eksamensprojekt\Datalogging_Statistics_Project-SystemTM\Snap7_Functions.py", line 131, in write_data_dbresult
    time_sec_byte_to_write = time_sec.to_bytes(4, byteorder='big')
                             ^^^^^^^^^^^^^^^^^
AttributeError: 'NoneType' object has no attribute 'to_bytes'
2024-03-19 07:47:52,096 - ERROR - Read setup file error: [Errno 2] No such file or directory: '1'
Traceback (most recent call last):
  File "c:\Users\STM\Desktop\Praktik_Eksamensprojekt\Datalogging_Statistics_Project-SystemTM\json_functions.py", line 7, in read_setup_file
    setup_file = open(f'{setup_file_name}')
                 ^^^^^^^^^^^^^^^^^^^^^^^^^^
FileNotFoundError: [Errno 2] No such file or directory: '1'
2024-03-19 07:47:52,097 - ERROR - Get plc from file error: 'NoneType' object has no attribute 'get'
Traceback (most recent call last):
  File "c:\Users\STM\Desktop\Praktik_Eksamensprojekt\Datalogging_Statistics_Project-SystemTM\json_functions.py", line 21, in get_plc_from_file
    plc1 = setup.get('PLC_1')
           ^^^^^^^^^
AttributeError: 'NoneType' object has no attribute 'get'
2024-03-19 07:47:52,097 - ERROR - Setup get sql column names from file error: 'NoneType' object has no attribute 'get'
Traceback (most recent call last):
  File "c:\Users\STM\Desktop\Praktik_Eksamensprojekt\Datalogging_Statistics_Project-SystemTM\json_functions.py", line 80, in setup_get_sql_column_names_from_file
    columns = plc1.get('column names')
              ^^^^^^^^
AttributeError: 'NoneType' object has no attribute 'get'
2024-03-19 07:47:52,098 - ERROR - Setup sql table from json error: 'NoneType' object is not iterable
Traceback (most recent call last):
  File "c:\Users\STM\Desktop\Praktik_Eksamensprojekt\Datalogging_Statistics_Project-SystemTM\SQLiteWrite.py", line 65, in setup_sql_table_from_json
    for I, column_dict in enumerate(json_setup_column_names):
                          ^^^^^^^^^^^^^^^^^^^^^^^^^^^^^^^^^^
TypeError: 'NoneType' object is not iterable
2024-03-19 07:47:54,565 - ERROR - Insert data into table error: table Test_Table has no column named Test_Data_Column_1
Traceback (most recent call last):
  File "c:\Users\STM\Desktop\Praktik_Eksamensprojekt\Datalogging_Statistics_Project-SystemTM\SQLiteWrite.py", line 23, in insert_data_into_table
    cursor.execute(insert_query, data)
sqlite3.OperationalError: table Test_Table has no column named Test_Data_Column_1
2024-03-19 07:47:54,567 - ERROR - Get seconds in range error: list index out of range
Traceback (most recent call last):
  File "c:\Users\STM\Desktop\Praktik_Eksamensprojekt\Datalogging_Statistics_Project-SystemTM\SQLiteRead.py", line 277, in get_seconds_in_range
    first_timestamp = datetime.strptime(timestamp_array[0]  , "%Y-%m-%d %H:%M:%S")
                                        ~~~~~~~~~~~~~~~^^^
IndexError: list index out of range
2024-03-19 07:47:54,567 - ERROR - Write data dbresult error: 'NoneType' object has no attribute 'to_bytes'
Traceback (most recent call last):
  File "c:\Users\STM\Desktop\Praktik_Eksamensprojekt\Datalogging_Statistics_Project-SystemTM\Snap7_Functions.py", line 131, in write_data_dbresult
    time_sec_byte_to_write = time_sec.to_bytes(4, byteorder='big')
                             ^^^^^^^^^^^^^^^^^
AttributeError: 'NoneType' object has no attribute 'to_bytes'
2024-03-19 07:48:03,922 - ERROR - Insert data into table error: table Test_Table has no column named Test_Data_Column_1
Traceback (most recent call last):
  File "c:\Users\STM\Desktop\Praktik_Eksamensprojekt\Datalogging_Statistics_Project-SystemTM\SQLiteWrite.py", line 23, in insert_data_into_table
    cursor.execute(insert_query, data)
sqlite3.OperationalError: table Test_Table has no column named Test_Data_Column_1
2024-03-19 07:48:03,924 - ERROR - Get seconds in range error: list index out of range
Traceback (most recent call last):
  File "c:\Users\STM\Desktop\Praktik_Eksamensprojekt\Datalogging_Statistics_Project-SystemTM\SQLiteRead.py", line 277, in get_seconds_in_range
    first_timestamp = datetime.strptime(timestamp_array[0]  , "%Y-%m-%d %H:%M:%S")
                                        ~~~~~~~~~~~~~~~^^^
IndexError: list index out of range
2024-03-19 07:48:03,924 - ERROR - Write data dbresult error: 'NoneType' object has no attribute 'to_bytes'
Traceback (most recent call last):
  File "c:\Users\STM\Desktop\Praktik_Eksamensprojekt\Datalogging_Statistics_Project-SystemTM\Snap7_Functions.py", line 131, in write_data_dbresult
    time_sec_byte_to_write = time_sec.to_bytes(4, byteorder='big')
                             ^^^^^^^^^^^^^^^^^
AttributeError: 'NoneType' object has no attribute 'to_bytes'
2024-03-19 07:52:11,107 - ERROR - Read setup file error: [Errno 2] No such file or directory: '1'
Traceback (most recent call last):
  File "c:\Users\STM\Desktop\Praktik_Eksamensprojekt\Datalogging_Statistics_Project-SystemTM\json_functions.py", line 7, in read_setup_file
    setup_file = open(f'{setup_file_name}')
                 ^^^^^^^^^^^^^^^^^^^^^^^^^^
FileNotFoundError: [Errno 2] No such file or directory: '1'
2024-03-19 07:52:11,107 - ERROR - Get plc from file error: 'NoneType' object has no attribute 'get'
Traceback (most recent call last):
  File "c:\Users\STM\Desktop\Praktik_Eksamensprojekt\Datalogging_Statistics_Project-SystemTM\json_functions.py", line 21, in get_plc_from_file
    plc1 = setup.get('PLC_1')
           ^^^^^^^^^
AttributeError: 'NoneType' object has no attribute 'get'
2024-03-19 07:52:11,109 - ERROR - Setup get sql column names from file error: 'NoneType' object has no attribute 'get'
Traceback (most recent call last):
  File "c:\Users\STM\Desktop\Praktik_Eksamensprojekt\Datalogging_Statistics_Project-SystemTM\json_functions.py", line 80, in setup_get_sql_column_names_from_file
    columns = plc1.get('column names')
              ^^^^^^^^
AttributeError: 'NoneType' object has no attribute 'get'
2024-03-19 07:52:11,109 - ERROR - Setup sql table from json error: 'NoneType' object is not iterable
Traceback (most recent call last):
  File "c:\Users\STM\Desktop\Praktik_Eksamensprojekt\Datalogging_Statistics_Project-SystemTM\SQLiteWrite.py", line 65, in setup_sql_table_from_json
    for I, column_dict in enumerate(json_setup_column_names):
                          ^^^^^^^^^^^^^^^^^^^^^^^^^^^^^^^^^^
TypeError: 'NoneType' object is not iterable
2024-03-19 07:52:11,140 - ERROR - Insert data into table error: table Test_Table has no column named Test_Data_Column_1
Traceback (most recent call last):
  File "c:\Users\STM\Desktop\Praktik_Eksamensprojekt\Datalogging_Statistics_Project-SystemTM\SQLiteWrite.py", line 23, in insert_data_into_table
    cursor.execute(insert_query, data)
sqlite3.OperationalError: table Test_Table has no column named Test_Data_Column_1
2024-03-19 07:52:11,142 - ERROR - Get seconds in range error: list index out of range
Traceback (most recent call last):
  File "c:\Users\STM\Desktop\Praktik_Eksamensprojekt\Datalogging_Statistics_Project-SystemTM\SQLiteRead.py", line 277, in get_seconds_in_range
    first_timestamp = datetime.strptime(timestamp_array[0]  , "%Y-%m-%d %H:%M:%S")
                                        ~~~~~~~~~~~~~~~^^^
IndexError: list index out of range
2024-03-19 07:52:11,143 - ERROR - Write data dbresult error: 'NoneType' object has no attribute 'to_bytes'
Traceback (most recent call last):
  File "c:\Users\STM\Desktop\Praktik_Eksamensprojekt\Datalogging_Statistics_Project-SystemTM\Snap7_Functions.py", line 131, in write_data_dbresult
    time_sec_byte_to_write = time_sec.to_bytes(4, byteorder='big')
                             ^^^^^^^^^^^^^^^^^
AttributeError: 'NoneType' object has no attribute 'to_bytes'
2024-03-19 07:52:21,140 - ERROR - Insert data into table error: table Test_Table has no column named Test_Data_Column_1
Traceback (most recent call last):
  File "c:\Users\STM\Desktop\Praktik_Eksamensprojekt\Datalogging_Statistics_Project-SystemTM\SQLiteWrite.py", line 23, in insert_data_into_table
    cursor.execute(insert_query, data)
sqlite3.OperationalError: table Test_Table has no column named Test_Data_Column_1
2024-03-19 07:52:21,142 - ERROR - Get seconds in range error: list index out of range
Traceback (most recent call last):
  File "c:\Users\STM\Desktop\Praktik_Eksamensprojekt\Datalogging_Statistics_Project-SystemTM\SQLiteRead.py", line 277, in get_seconds_in_range
    first_timestamp = datetime.strptime(timestamp_array[0]  , "%Y-%m-%d %H:%M:%S")
                                        ~~~~~~~~~~~~~~~^^^
IndexError: list index out of range
2024-03-19 07:52:21,142 - ERROR - Write data dbresult error: 'NoneType' object has no attribute 'to_bytes'
Traceback (most recent call last):
  File "c:\Users\STM\Desktop\Praktik_Eksamensprojekt\Datalogging_Statistics_Project-SystemTM\Snap7_Functions.py", line 131, in write_data_dbresult
    time_sec_byte_to_write = time_sec.to_bytes(4, byteorder='big')
                             ^^^^^^^^^^^^^^^^^
AttributeError: 'NoneType' object has no attribute 'to_bytes'
2024-03-19 07:55:01,327 - ERROR - Read setup file error: [Errno 2] No such file or directory: "{'PLC_1': [{'ip address': '172.31.1.60', 'rack': 0, 'slot': 1, 'tcpport': 102, 'dbinsert db number': 10, 'dbinsert_logging_trigger index': 0, 'dbinsert data index': 4, 'dbresult db number': 11, 'dbresult time_sec index': 0, 'dbresult data index': 4, 'table name': 'Test_Table', 'column names': [{'column 1': 'TimeStamp'}, {'column 2': 'Test_Data_Column_1'}, {'column 3': 'add_test'}, {'column 4': 'Test_Data_Column_3'}, {'column 5': 'Motor 1'}, {'column 6': 'Test_Data_Column_5'}, {'column 7': 'Test_Data_Column_6'}, {'column 8': 'Test_Data_Column_7'}, {'column 9': 'Test_Data_Column_8'}]}]}"
Traceback (most recent call last):
  File "c:\Users\STM\Desktop\Praktik_Eksamensprojekt\Datalogging_Statistics_Project-SystemTM\json_functions.py", line 7, in read_setup_file
    setup_file = open(f'{setup_file_name}')
                 ^^^^^^^^^^^^^^^^^^^^^^^^^^
FileNotFoundError: [Errno 2] No such file or directory: "{'PLC_1': [{'ip address': '172.31.1.60', 'rack': 0, 'slot': 1, 'tcpport': 102, 'dbinsert db number': 10, 'dbinsert_logging_trigger index': 0, 'dbinsert data index': 4, 'dbresult db number': 11, 'dbresult time_sec index': 0, 'dbresult data index': 4, 'table name': 'Test_Table', 'column names': [{'column 1': 'TimeStamp'}, {'column 2': 'Test_Data_Column_1'}, {'column 3': 'add_test'}, {'column 4': 'Test_Data_Column_3'}, {'column 5': 'Motor 1'}, {'column 6': 'Test_Data_Column_5'}, {'column 7': 'Test_Data_Column_6'}, {'column 8': 'Test_Data_Column_7'}, {'column 9': 'Test_Data_Column_8'}]}]}"
2024-03-19 07:55:01,327 - ERROR - Get plc from file error: 'NoneType' object has no attribute 'get'
Traceback (most recent call last):
  File "c:\Users\STM\Desktop\Praktik_Eksamensprojekt\Datalogging_Statistics_Project-SystemTM\json_functions.py", line 21, in get_plc_from_file
    plc1 = setup.get('PLC_1')
           ^^^^^^^^^
AttributeError: 'NoneType' object has no attribute 'get'
2024-03-19 07:55:01,327 - ERROR - Setup get sql column names from file error: 'NoneType' object has no attribute 'get'
Traceback (most recent call last):
  File "c:\Users\STM\Desktop\Praktik_Eksamensprojekt\Datalogging_Statistics_Project-SystemTM\json_functions.py", line 80, in setup_get_sql_column_names_from_file
    columns = plc1.get('column names')
              ^^^^^^^^
AttributeError: 'NoneType' object has no attribute 'get'
2024-03-19 07:55:01,328 - ERROR - Setup sql table from json error: 'NoneType' object is not iterable
Traceback (most recent call last):
  File "c:\Users\STM\Desktop\Praktik_Eksamensprojekt\Datalogging_Statistics_Project-SystemTM\SQLiteWrite.py", line 65, in setup_sql_table_from_json
    for I, column_dict in enumerate(json_setup_column_names):
                          ^^^^^^^^^^^^^^^^^^^^^^^^^^^^^^^^^^
TypeError: 'NoneType' object is not iterable
2024-03-19 07:55:01,355 - ERROR - Insert data into table error: table Test_Table has no column named Test_Data_Column_1
Traceback (most recent call last):
  File "c:\Users\STM\Desktop\Praktik_Eksamensprojekt\Datalogging_Statistics_Project-SystemTM\SQLiteWrite.py", line 23, in insert_data_into_table
    cursor.execute(insert_query, data)
sqlite3.OperationalError: table Test_Table has no column named Test_Data_Column_1
2024-03-19 07:55:01,356 - ERROR - Get seconds in range error: list index out of range
Traceback (most recent call last):
  File "c:\Users\STM\Desktop\Praktik_Eksamensprojekt\Datalogging_Statistics_Project-SystemTM\SQLiteRead.py", line 277, in get_seconds_in_range
    first_timestamp = datetime.strptime(timestamp_array[0]  , "%Y-%m-%d %H:%M:%S")
                                        ~~~~~~~~~~~~~~~^^^
IndexError: list index out of range
2024-03-19 07:55:01,357 - ERROR - Write data dbresult error: 'NoneType' object has no attribute 'to_bytes'
Traceback (most recent call last):
  File "c:\Users\STM\Desktop\Praktik_Eksamensprojekt\Datalogging_Statistics_Project-SystemTM\Snap7_Functions.py", line 131, in write_data_dbresult
    time_sec_byte_to_write = time_sec.to_bytes(4, byteorder='big')
                             ^^^^^^^^^^^^^^^^^
AttributeError: 'NoneType' object has no attribute 'to_bytes'
2024-03-19 07:55:13,908 - ERROR - Read setup file error: [Errno 2] No such file or directory: "{'PLC_1': [{'ip address': '172.31.1.60', 'rack': 0, 'slot': 1, 'tcpport': 102, 'dbinsert db number': 10, 'dbinsert_logging_trigger index': 0, 'dbinsert data index': 4, 'dbresult db number': 11, 'dbresult time_sec index': 0, 'dbresult data index': 4, 'table name': 'Test_Table', 'column names': [{'column 1': 'TimeStamp'}, {'column 2': 'Test_Data_Column_1'}, {'column 3': 'add_test'}, {'column 4': 'Test_Data_Column_3'}, {'column 5': 'Motor 1'}, {'column 6': 'Test_Data_Column_5'}, {'column 7': 'Test_Data_Column_6'}, {'column 8': 'Test_Data_Column_7'}, {'column 9': 'Test_Data_Column_8'}]}]}"
Traceback (most recent call last):
  File "c:\Users\STM\Desktop\Praktik_Eksamensprojekt\Datalogging_Statistics_Project-SystemTM\json_functions.py", line 7, in read_setup_file
    setup_file = open(f'{setup_file_name}')
                 ^^^^^^^^^^^^^^^^^^^^^^^^^^
FileNotFoundError: [Errno 2] No such file or directory: "{'PLC_1': [{'ip address': '172.31.1.60', 'rack': 0, 'slot': 1, 'tcpport': 102, 'dbinsert db number': 10, 'dbinsert_logging_trigger index': 0, 'dbinsert data index': 4, 'dbresult db number': 11, 'dbresult time_sec index': 0, 'dbresult data index': 4, 'table name': 'Test_Table', 'column names': [{'column 1': 'TimeStamp'}, {'column 2': 'Test_Data_Column_1'}, {'column 3': 'add_test'}, {'column 4': 'Test_Data_Column_3'}, {'column 5': 'Motor 1'}, {'column 6': 'Test_Data_Column_5'}, {'column 7': 'Test_Data_Column_6'}, {'column 8': 'Test_Data_Column_7'}, {'column 9': 'Test_Data_Column_8'}]}]}"
2024-03-19 07:55:13,908 - ERROR - Get plc from file error: 'NoneType' object has no attribute 'get'
Traceback (most recent call last):
  File "c:\Users\STM\Desktop\Praktik_Eksamensprojekt\Datalogging_Statistics_Project-SystemTM\json_functions.py", line 21, in get_plc_from_file
    plc1 = setup.get('PLC_1')
           ^^^^^^^^^
AttributeError: 'NoneType' object has no attribute 'get'
2024-03-19 07:55:13,909 - ERROR - Setup get sql column names from file error: 'NoneType' object has no attribute 'get'
Traceback (most recent call last):
  File "c:\Users\STM\Desktop\Praktik_Eksamensprojekt\Datalogging_Statistics_Project-SystemTM\json_functions.py", line 80, in setup_get_sql_column_names_from_file
    columns = plc1.get('column names')
              ^^^^^^^^
AttributeError: 'NoneType' object has no attribute 'get'
2024-03-19 07:55:13,910 - ERROR - Setup sql table from json error: 'NoneType' object is not iterable
Traceback (most recent call last):
  File "c:\Users\STM\Desktop\Praktik_Eksamensprojekt\Datalogging_Statistics_Project-SystemTM\SQLiteWrite.py", line 65, in setup_sql_table_from_json
    for I, column_dict in enumerate(json_setup_column_names):
                          ^^^^^^^^^^^^^^^^^^^^^^^^^^^^^^^^^^
TypeError: 'NoneType' object is not iterable
2024-03-19 07:55:21,362 - ERROR - Insert data into table error: table Test_Table has no column named Test_Data_Column_1
Traceback (most recent call last):
  File "c:\Users\STM\Desktop\Praktik_Eksamensprojekt\Datalogging_Statistics_Project-SystemTM\SQLiteWrite.py", line 23, in insert_data_into_table
    cursor.execute(insert_query, data)
sqlite3.OperationalError: table Test_Table has no column named Test_Data_Column_1
2024-03-19 07:55:21,365 - ERROR - Get seconds in range error: list index out of range
Traceback (most recent call last):
  File "c:\Users\STM\Desktop\Praktik_Eksamensprojekt\Datalogging_Statistics_Project-SystemTM\SQLiteRead.py", line 277, in get_seconds_in_range
    first_timestamp = datetime.strptime(timestamp_array[0]  , "%Y-%m-%d %H:%M:%S")
                                        ~~~~~~~~~~~~~~~^^^
IndexError: list index out of range
2024-03-19 07:55:21,366 - ERROR - Write data dbresult error: 'NoneType' object has no attribute 'to_bytes'
Traceback (most recent call last):
  File "c:\Users\STM\Desktop\Praktik_Eksamensprojekt\Datalogging_Statistics_Project-SystemTM\Snap7_Functions.py", line 131, in write_data_dbresult
    time_sec_byte_to_write = time_sec.to_bytes(4, byteorder='big')
                             ^^^^^^^^^^^^^^^^^
AttributeError: 'NoneType' object has no attribute 'to_bytes'
2024-03-19 10:15:54,035 - ERROR - Main script error: asyncio.run() cannot be called from a running event loop
Traceback (most recent call last):
  File "c:\Users\STM\Desktop\Praktik_Eksamensprojekt\Datalogging_Statistics_Project-SystemTM\Main.py", line 132, in main_script
    asyncio.run(main_script_snap7_start(sql_db_path, setup_file_step7))
  File "C:\Users\STM\AppData\Local\Programs\Python\Python312\Lib\asyncio\runners.py", line 190, in run
    raise RuntimeError(
RuntimeError: asyncio.run() cannot be called from a running event loop
2024-03-19 10:29:02,227 - ERROR - b' ISO : An error occurred during recv TCP : Connection timed out'
2024-03-19 10:29:02,228 - ERROR - Connect snap7 client error: b' ISO : An error occurred during recv TCP : Connection timed out'
Traceback (most recent call last):
  File "c:\Users\STM\Desktop\Praktik_Eksamensprojekt\Datalogging_Statistics_Project-SystemTM\Snap7_Functions.py", line 18, in connect_snap7_client
    client.connect(ip_address, rack, slot, tcpport)
  File "C:\Users\STM\AppData\Local\Programs\Python\Python312\Lib\site-packages\snap7\client\__init__.py", line 24, in f
    check_error(code, context="client")
  File "C:\Users\STM\AppData\Local\Programs\Python\Python312\Lib\site-packages\snap7\common.py", line 89, in check_error
    raise RuntimeError(error)
RuntimeError: b' ISO : An error occurred during recv TCP : Connection timed out'
2024-03-19 10:29:02,237 - ERROR - Monitor and insert data snap7 error: 'NoneType' object has no attribute 'db_write'
Traceback (most recent call last):
  File "c:\Users\STM\Desktop\Praktik_Eksamensprojekt\Datalogging_Statistics_Project-SystemTM\Snap7_Functions.py", line 104, in monitor_and_insert_data_snap7
    data_array = monitor_and_get_data_on_trigger_snap7(client, setup_file_step7)
                 ^^^^^^^^^^^^^^^^^^^^^^^^^^^^^^^^^^^^^^^^^^^^^^^^^^^^^^^^^^^^^^^
  File "c:\Users\STM\Desktop\Praktik_Eksamensprojekt\Datalogging_Statistics_Project-SystemTM\Snap7_Functions.py", line 80, in monitor_and_get_data_on_trigger_snap7
    client.db_write(db_number, logging_trigger_index, bytearray_to_write)
    ^^^^^^^^^^^^^^^
AttributeError: 'NoneType' object has no attribute 'db_write'
2024-03-19 10:29:02,765 - ERROR - Insert data into table error: UNIQUE constraint failed: Test_Table.TimeStamp
Traceback (most recent call last):
  File "c:\Users\STM\Desktop\Praktik_Eksamensprojekt\Datalogging_Statistics_Project-SystemTM\SQLiteWrite.py", line 23, in insert_data_into_table
    cursor.execute(insert_query, data)
sqlite3.IntegrityError: UNIQUE constraint failed: Test_Table.TimeStamp
2024-03-19 10:29:04,749 - ERROR - Insert data into table error: UNIQUE constraint failed: Test_Table.TimeStamp
Traceback (most recent call last):
  File "c:\Users\STM\Desktop\Praktik_Eksamensprojekt\Datalogging_Statistics_Project-SystemTM\SQLiteWrite.py", line 23, in insert_data_into_table
    cursor.execute(insert_query, data)
sqlite3.IntegrityError: UNIQUE constraint failed: Test_Table.TimeStamp
2024-03-20 15:21:18,480 - ERROR - b'CPU : Item not available'
2024-03-20 15:21:18,480 - ERROR - Get data array from db error: b'CPU : Item not available'
Traceback (most recent call last):
  File "c:\Users\STM\Desktop\Praktik_Eksamensprojekt\Datalogging_Statistics_Project-SystemTM\Snap7_Functions.py", line 55, in get_data_array_from_plc_db
    data = client.db_read(db_number, data_index, setup_file_get_number_of_data_columns(setup_file_step7)*4)
           ^^^^^^^^^^^^^^^^^^^^^^^^^^^^^^^^^^^^^^^^^^^^^^^^^^^^^^^^^^^^^^^^^^^^^^^^^^^^^^^^^^^^^^^^^^^^^^^^
  File "C:\Users\STM\AppData\Local\Programs\Python\Python312\Lib\site-packages\snap7\client\__init__.py", line 226, in db_read
    check_error(result, context="client")
  File "C:\Users\STM\AppData\Local\Programs\Python\Python312\Lib\site-packages\snap7\common.py", line 89, in check_error
    raise RuntimeError(error)
RuntimeError: b'CPU : Item not available'
2024-03-22 08:27:09,673 - ERROR - b' ISO : Datasize passed to send/recv buffer is invalid'
2024-03-22 08:29:36,001 - ERROR - b' ISO : Datasize passed to send/recv buffer is invalid'
2024-03-22 08:30:33,187 - ERROR - b' ISO : Datasize passed to send/recv buffer is invalid'
2024-03-22 08:31:15,207 - ERROR - b' ISO : An error occurred during send TCP : Connection timed out'
2024-03-22 08:33:58,671 - ERROR - Get log data within range error: near "WHERE": syntax error
Traceback (most recent call last):
  File "c:\Users\STM\Desktop\Praktik_Eksamensprojekt\Datalogging_Statistics_Project-SystemTM\SQLiteRead.py", line 153, in get_log_data_within_range
    cursor.execute(f"SELECT * FROM {table} WHERE TimeStamp BETWEEN '{min_range_utc}' AND '{max_range_utc}';")
sqlite3.OperationalError: near "WHERE": syntax error
2024-03-22 08:34:17,785 - ERROR - Get log data within range error: near "WHERE": syntax error
Traceback (most recent call last):
  File "c:\Users\STM\Desktop\Praktik_Eksamensprojekt\Datalogging_Statistics_Project-SystemTM\SQLiteRead.py", line 153, in get_log_data_within_range
    cursor.execute(f"SELECT * FROM {table} WHERE TimeStamp BETWEEN '{min_range_utc}' AND '{max_range_utc}';")
sqlite3.OperationalError: near "WHERE": syntax error
2024-03-25 10:05:49,611 - ERROR - Main snap7 script error: monitor_and_insert_data_snap7() takes 3 positional arguments but 5 were given
Traceback (most recent call last):
  File "c:\Users\STM\Desktop\Praktik_Eksamensprojekt\Datalogging_Statistics_Project-SystemTM\Main.py", line 126, in main_script_snap7_start
    monitor_and_insert_data_snap7(db_manager.sql_db_path, db_manager.table_name, db_manager.setup_file, test_min_range, test_max_range)
TypeError: monitor_and_insert_data_snap7() takes 3 positional arguments but 5 were given
2024-03-25 10:06:41,440 - ERROR - Get data array from db error: 'function' object has no attribute 'get'
Traceback (most recent call last):
  File "c:\Users\STM\Desktop\Praktik_Eksamensprojekt\Datalogging_Statistics_Project-SystemTM\Snap7_Functions.py", line 53, in get_data_array_from_plc_db
    data_index = get_plc_from_file.get('dbinsert data index')
                 ^^^^^^^^^^^^^^^^^^^^^
AttributeError: 'function' object has no attribute 'get'
2024-03-25 10:06:41,445 - ERROR - b'CLI : Cannot change this param now'
2024-03-25 10:06:41,446 - ERROR - Connect snap7 client error: b'CLI : Cannot change this param now'
Traceback (most recent call last):
  File "c:\Users\STM\Desktop\Praktik_Eksamensprojekt\Datalogging_Statistics_Project-SystemTM\Snap7_Functions.py", line 17, in connect_snap7_client
    client.connect(ip_address, rack, slot, tcpport)
  File "C:\Users\STM\AppData\Local\Programs\Python\Python312\Lib\site-packages\snap7\client\__init__.py", line 23, in f
    code = func(*args, **kw)
           ^^^^^^^^^^^^^^^^^
  File "C:\Users\STM\AppData\Local\Programs\Python\Python312\Lib\site-packages\snap7\client\__init__.py", line 192, in connect
    self.set_param(RemotePort, tcpport)
  File "C:\Users\STM\AppData\Local\Programs\Python\Python312\Lib\site-packages\snap7\client\__init__.py", line 24, in f
    check_error(code, context="client")
  File "C:\Users\STM\AppData\Local\Programs\Python\Python312\Lib\site-packages\snap7\common.py", line 89, in check_error
    raise RuntimeError(error)
RuntimeError: b'CLI : Cannot change this param now'
2024-03-25 10:06:41,456 - ERROR - Get data from plc db error: 'NoneType' object has no attribute 'db_read'
Traceback (most recent call last):
  File "c:\Users\STM\Desktop\Praktik_Eksamensprojekt\Datalogging_Statistics_Project-SystemTM\Snap7_Functions.py", line 41, in get_data_from_plc_db
    data = client.db_read(db_number, index, index+4)
           ^^^^^^^^^^^^^^
AttributeError: 'NoneType' object has no attribute 'db_read'
2024-03-25 10:06:46,439 - ERROR - Get data array from db error: 'function' object has no attribute 'get'
Traceback (most recent call last):
  File "c:\Users\STM\Desktop\Praktik_Eksamensprojekt\Datalogging_Statistics_Project-SystemTM\Snap7_Functions.py", line 53, in get_data_array_from_plc_db
    data_index = get_plc_from_file.get('dbinsert data index')
                 ^^^^^^^^^^^^^^^^^^^^^
AttributeError: 'function' object has no attribute 'get'
2024-03-25 10:06:46,442 - ERROR - b'CLI : Cannot change this param now'
2024-03-25 10:06:46,442 - ERROR - Connect snap7 client error: b'CLI : Cannot change this param now'
Traceback (most recent call last):
  File "c:\Users\STM\Desktop\Praktik_Eksamensprojekt\Datalogging_Statistics_Project-SystemTM\Snap7_Functions.py", line 17, in connect_snap7_client
    client.connect(ip_address, rack, slot, tcpport)
  File "C:\Users\STM\AppData\Local\Programs\Python\Python312\Lib\site-packages\snap7\client\__init__.py", line 23, in f
    code = func(*args, **kw)
           ^^^^^^^^^^^^^^^^^
  File "C:\Users\STM\AppData\Local\Programs\Python\Python312\Lib\site-packages\snap7\client\__init__.py", line 192, in connect
    self.set_param(RemotePort, tcpport)
  File "C:\Users\STM\AppData\Local\Programs\Python\Python312\Lib\site-packages\snap7\client\__init__.py", line 24, in f
    check_error(code, context="client")
  File "C:\Users\STM\AppData\Local\Programs\Python\Python312\Lib\site-packages\snap7\common.py", line 89, in check_error
    raise RuntimeError(error)
RuntimeError: b'CLI : Cannot change this param now'
2024-03-25 10:06:46,446 - ERROR - Get data from plc db error: 'NoneType' object has no attribute 'db_read'
Traceback (most recent call last):
  File "c:\Users\STM\Desktop\Praktik_Eksamensprojekt\Datalogging_Statistics_Project-SystemTM\Snap7_Functions.py", line 41, in get_data_from_plc_db
    data = client.db_read(db_number, index, index+4)
           ^^^^^^^^^^^^^^
AttributeError: 'NoneType' object has no attribute 'db_read'
2024-03-25 10:06:51,443 - ERROR - Get data array from db error: 'function' object has no attribute 'get'
Traceback (most recent call last):
  File "c:\Users\STM\Desktop\Praktik_Eksamensprojekt\Datalogging_Statistics_Project-SystemTM\Snap7_Functions.py", line 53, in get_data_array_from_plc_db
    data_index = get_plc_from_file.get('dbinsert data index')
                 ^^^^^^^^^^^^^^^^^^^^^
AttributeError: 'function' object has no attribute 'get'
2024-03-25 10:06:51,449 - ERROR - b'CLI : Cannot change this param now'
2024-03-25 10:06:51,450 - ERROR - Connect snap7 client error: b'CLI : Cannot change this param now'
Traceback (most recent call last):
  File "c:\Users\STM\Desktop\Praktik_Eksamensprojekt\Datalogging_Statistics_Project-SystemTM\Snap7_Functions.py", line 17, in connect_snap7_client
    client.connect(ip_address, rack, slot, tcpport)
  File "C:\Users\STM\AppData\Local\Programs\Python\Python312\Lib\site-packages\snap7\client\__init__.py", line 23, in f
    code = func(*args, **kw)
           ^^^^^^^^^^^^^^^^^
  File "C:\Users\STM\AppData\Local\Programs\Python\Python312\Lib\site-packages\snap7\client\__init__.py", line 192, in connect
    self.set_param(RemotePort, tcpport)
  File "C:\Users\STM\AppData\Local\Programs\Python\Python312\Lib\site-packages\snap7\client\__init__.py", line 24, in f
    check_error(code, context="client")
  File "C:\Users\STM\AppData\Local\Programs\Python\Python312\Lib\site-packages\snap7\common.py", line 89, in check_error
    raise RuntimeError(error)
RuntimeError: b'CLI : Cannot change this param now'
2024-03-25 10:06:51,453 - ERROR - Get data from plc db error: 'NoneType' object has no attribute 'db_read'
Traceback (most recent call last):
  File "c:\Users\STM\Desktop\Praktik_Eksamensprojekt\Datalogging_Statistics_Project-SystemTM\Snap7_Functions.py", line 41, in get_data_from_plc_db
    data = client.db_read(db_number, index, index+4)
           ^^^^^^^^^^^^^^
AttributeError: 'NoneType' object has no attribute 'db_read'
2024-03-25 10:06:56,447 - ERROR - Get data array from db error: 'function' object has no attribute 'get'
Traceback (most recent call last):
  File "c:\Users\STM\Desktop\Praktik_Eksamensprojekt\Datalogging_Statistics_Project-SystemTM\Snap7_Functions.py", line 53, in get_data_array_from_plc_db
    data_index = get_plc_from_file.get('dbinsert data index')
                 ^^^^^^^^^^^^^^^^^^^^^
AttributeError: 'function' object has no attribute 'get'
2024-03-25 10:06:56,450 - ERROR - b'CLI : Cannot change this param now'
2024-03-25 10:06:56,450 - ERROR - Connect snap7 client error: b'CLI : Cannot change this param now'
Traceback (most recent call last):
  File "c:\Users\STM\Desktop\Praktik_Eksamensprojekt\Datalogging_Statistics_Project-SystemTM\Snap7_Functions.py", line 17, in connect_snap7_client
    client.connect(ip_address, rack, slot, tcpport)
  File "C:\Users\STM\AppData\Local\Programs\Python\Python312\Lib\site-packages\snap7\client\__init__.py", line 23, in f
    code = func(*args, **kw)
           ^^^^^^^^^^^^^^^^^
  File "C:\Users\STM\AppData\Local\Programs\Python\Python312\Lib\site-packages\snap7\client\__init__.py", line 192, in connect
    self.set_param(RemotePort, tcpport)
  File "C:\Users\STM\AppData\Local\Programs\Python\Python312\Lib\site-packages\snap7\client\__init__.py", line 24, in f
    check_error(code, context="client")
  File "C:\Users\STM\AppData\Local\Programs\Python\Python312\Lib\site-packages\snap7\common.py", line 89, in check_error
    raise RuntimeError(error)
RuntimeError: b'CLI : Cannot change this param now'
2024-03-25 10:06:56,452 - ERROR - Get data from plc db error: 'NoneType' object has no attribute 'db_read'
Traceback (most recent call last):
  File "c:\Users\STM\Desktop\Praktik_Eksamensprojekt\Datalogging_Statistics_Project-SystemTM\Snap7_Functions.py", line 41, in get_data_from_plc_db
    data = client.db_read(db_number, index, index+4)
           ^^^^^^^^^^^^^^
AttributeError: 'NoneType' object has no attribute 'db_read'
2024-03-25 10:10:43,235 - ERROR - Get data array from db error: 'function' object has no attribute 'get'
Traceback (most recent call last):
  File "c:\Users\STM\Desktop\Praktik_Eksamensprojekt\Datalogging_Statistics_Project-SystemTM\Snap7_Functions.py", line 53, in get_data_array_from_plc_db
    data_index = get_plc_from_file.get('dbinsert data index')
                 ^^^^^^^^^^^^^^^^^^^^^
AttributeError: 'function' object has no attribute 'get'
2024-03-25 10:10:43,239 - ERROR - b'CLI : Cannot change this param now'
2024-03-25 10:10:43,239 - ERROR - Connect snap7 client error: b'CLI : Cannot change this param now'
Traceback (most recent call last):
  File "c:\Users\STM\Desktop\Praktik_Eksamensprojekt\Datalogging_Statistics_Project-SystemTM\Snap7_Functions.py", line 17, in connect_snap7_client
    client.connect(ip_address, rack, slot, tcpport)
  File "C:\Users\STM\AppData\Local\Programs\Python\Python312\Lib\site-packages\snap7\client\__init__.py", line 23, in f
    code = func(*args, **kw)
           ^^^^^^^^^^^^^^^^^
  File "C:\Users\STM\AppData\Local\Programs\Python\Python312\Lib\site-packages\snap7\client\__init__.py", line 192, in connect
    self.set_param(RemotePort, tcpport)
  File "C:\Users\STM\AppData\Local\Programs\Python\Python312\Lib\site-packages\snap7\client\__init__.py", line 24, in f
    check_error(code, context="client")
  File "C:\Users\STM\AppData\Local\Programs\Python\Python312\Lib\site-packages\snap7\common.py", line 89, in check_error
    raise RuntimeError(error)
RuntimeError: b'CLI : Cannot change this param now'
2024-03-25 10:10:43,241 - ERROR - Get data from plc db error: 'NoneType' object has no attribute 'db_read'
Traceback (most recent call last):
  File "c:\Users\STM\Desktop\Praktik_Eksamensprojekt\Datalogging_Statistics_Project-SystemTM\Snap7_Functions.py", line 41, in get_data_from_plc_db
    data = client.db_read(db_number, index, index+4)
           ^^^^^^^^^^^^^^
AttributeError: 'NoneType' object has no attribute 'db_read'
2024-03-25 10:16:29,832 - ERROR - Get data array from db error: 'function' object has no attribute 'get'
Traceback (most recent call last):
  File "c:\Users\STM\Desktop\Praktik_Eksamensprojekt\Datalogging_Statistics_Project-SystemTM\Snap7_Functions.py", line 53, in get_data_array_from_plc_db
    data_index = get_plc_from_file.get('dbinsert data index')
                 ^^^^^^^^^^^^^^^^^^^^^
AttributeError: 'function' object has no attribute 'get'
2024-03-25 10:16:29,837 - ERROR - b'CLI : Cannot change this param now'
2024-03-25 10:16:29,837 - ERROR - Connect snap7 client error: b'CLI : Cannot change this param now'
Traceback (most recent call last):
  File "c:\Users\STM\Desktop\Praktik_Eksamensprojekt\Datalogging_Statistics_Project-SystemTM\Snap7_Functions.py", line 17, in connect_snap7_client
    client.connect(ip_address, rack, slot, tcpport)
  File "C:\Users\STM\AppData\Local\Programs\Python\Python312\Lib\site-packages\snap7\client\__init__.py", line 23, in f
    code = func(*args, **kw)
           ^^^^^^^^^^^^^^^^^
  File "C:\Users\STM\AppData\Local\Programs\Python\Python312\Lib\site-packages\snap7\client\__init__.py", line 192, in connect
    self.set_param(RemotePort, tcpport)
  File "C:\Users\STM\AppData\Local\Programs\Python\Python312\Lib\site-packages\snap7\client\__init__.py", line 24, in f
    check_error(code, context="client")
  File "C:\Users\STM\AppData\Local\Programs\Python\Python312\Lib\site-packages\snap7\common.py", line 89, in check_error
    raise RuntimeError(error)
RuntimeError: b'CLI : Cannot change this param now'
2024-03-25 10:16:29,840 - ERROR - Get data from plc db error: 'NoneType' object has no attribute 'db_read'
Traceback (most recent call last):
  File "c:\Users\STM\Desktop\Praktik_Eksamensprojekt\Datalogging_Statistics_Project-SystemTM\Snap7_Functions.py", line 41, in get_data_from_plc_db
    data = client.db_read(db_number, index, index+4)
           ^^^^^^^^^^^^^^
AttributeError: 'NoneType' object has no attribute 'db_read'
2024-03-25 10:19:24,376 - ERROR - Get data array from db error: 'function' object has no attribute 'get'
Traceback (most recent call last):
  File "c:\Users\STM\Desktop\Praktik_Eksamensprojekt\Datalogging_Statistics_Project-SystemTM\Snap7_Functions.py", line 53, in get_data_array_from_plc_db
    data_index = get_plc_from_file.get('dbinsert data index')
                 ^^^^^^^^^^^^^^^^^^^^^
AttributeError: 'function' object has no attribute 'get'
2024-03-25 10:19:24,381 - ERROR - b'CLI : Cannot change this param now'
2024-03-25 10:19:24,381 - ERROR - Connect snap7 client error: b'CLI : Cannot change this param now'
Traceback (most recent call last):
  File "c:\Users\STM\Desktop\Praktik_Eksamensprojekt\Datalogging_Statistics_Project-SystemTM\Snap7_Functions.py", line 17, in connect_snap7_client
    client.connect(ip_address, rack, slot, tcpport)
  File "C:\Users\STM\AppData\Local\Programs\Python\Python312\Lib\site-packages\snap7\client\__init__.py", line 23, in f
    code = func(*args, **kw)
           ^^^^^^^^^^^^^^^^^
  File "C:\Users\STM\AppData\Local\Programs\Python\Python312\Lib\site-packages\snap7\client\__init__.py", line 192, in connect
    self.set_param(RemotePort, tcpport)
  File "C:\Users\STM\AppData\Local\Programs\Python\Python312\Lib\site-packages\snap7\client\__init__.py", line 24, in f
    check_error(code, context="client")
  File "C:\Users\STM\AppData\Local\Programs\Python\Python312\Lib\site-packages\snap7\common.py", line 89, in check_error
    raise RuntimeError(error)
RuntimeError: b'CLI : Cannot change this param now'
2024-03-25 10:19:24,384 - ERROR - Get data from plc db error: 'NoneType' object has no attribute 'db_read'
Traceback (most recent call last):
  File "c:\Users\STM\Desktop\Praktik_Eksamensprojekt\Datalogging_Statistics_Project-SystemTM\Snap7_Functions.py", line 41, in get_data_from_plc_db
    data = client.db_read(db_number, index, index+4)
           ^^^^^^^^^^^^^^
AttributeError: 'NoneType' object has no attribute 'db_read'
2024-03-25 10:29:31,618 - ERROR - Get data array from db error: 'function' object has no attribute 'get'
Traceback (most recent call last):
  File "c:\Users\STM\Desktop\Praktik_Eksamensprojekt\Datalogging_Statistics_Project-SystemTM\Snap7_Functions.py", line 54, in get_data_array_from_plc_db
    data_index = get_plc_from_file.get('dbinsert data index')
                 ^^^^^^^^^^^^^^^^^^^^^
AttributeError: 'function' object has no attribute 'get'
2024-03-25 10:29:31,624 - ERROR - b'CLI : Cannot change this param now'
2024-03-25 10:29:31,625 - ERROR - Connect snap7 client error: b'CLI : Cannot change this param now'
Traceback (most recent call last):
  File "c:\Users\STM\Desktop\Praktik_Eksamensprojekt\Datalogging_Statistics_Project-SystemTM\Snap7_Functions.py", line 17, in connect_snap7_client
    client.connect(ip_address, rack, slot, tcpport)
  File "C:\Users\STM\AppData\Local\Programs\Python\Python312\Lib\site-packages\snap7\client\__init__.py", line 23, in f
    code = func(*args, **kw)
           ^^^^^^^^^^^^^^^^^
  File "C:\Users\STM\AppData\Local\Programs\Python\Python312\Lib\site-packages\snap7\client\__init__.py", line 192, in connect
    self.set_param(RemotePort, tcpport)
  File "C:\Users\STM\AppData\Local\Programs\Python\Python312\Lib\site-packages\snap7\client\__init__.py", line 24, in f
    check_error(code, context="client")
  File "C:\Users\STM\AppData\Local\Programs\Python\Python312\Lib\site-packages\snap7\common.py", line 89, in check_error
    raise RuntimeError(error)
RuntimeError: b'CLI : Cannot change this param now'
2024-03-25 10:29:31,628 - ERROR - Get data from plc db error: 'NoneType' object has no attribute 'db_read'
Traceback (most recent call last):
  File "c:\Users\STM\Desktop\Praktik_Eksamensprojekt\Datalogging_Statistics_Project-SystemTM\Snap7_Functions.py", line 41, in get_data_from_plc_db
    data = client.db_read(db_number, index, index+4)
           ^^^^^^^^^^^^^^
AttributeError: 'NoneType' object has no attribute 'db_read'
2024-03-25 10:31:04,312 - ERROR - Insert data into table error: table Test_Table has no column named TotalMeters
Traceback (most recent call last):
  File "c:\Users\STM\Desktop\Praktik_Eksamensprojekt\Datalogging_Statistics_Project-SystemTM\SQLiteWrite.py", line 24, in insert_data_into_table
    cursor.execute(insert_query, data)
sqlite3.OperationalError: table Test_Table has no column named TotalMeters
2024-03-25 10:31:04,313 - ERROR - b'CLI : Cannot change this param now'
2024-03-25 10:31:04,313 - ERROR - Connect snap7 client error: b'CLI : Cannot change this param now'
Traceback (most recent call last):
  File "c:\Users\STM\Desktop\Praktik_Eksamensprojekt\Datalogging_Statistics_Project-SystemTM\Snap7_Functions.py", line 17, in connect_snap7_client
    client.connect(ip_address, rack, slot, tcpport)
  File "C:\Users\STM\AppData\Local\Programs\Python\Python312\Lib\site-packages\snap7\client\__init__.py", line 23, in f
    code = func(*args, **kw)
           ^^^^^^^^^^^^^^^^^
  File "C:\Users\STM\AppData\Local\Programs\Python\Python312\Lib\site-packages\snap7\client\__init__.py", line 192, in connect
    self.set_param(RemotePort, tcpport)
  File "C:\Users\STM\AppData\Local\Programs\Python\Python312\Lib\site-packages\snap7\client\__init__.py", line 24, in f
    check_error(code, context="client")
  File "C:\Users\STM\AppData\Local\Programs\Python\Python312\Lib\site-packages\snap7\common.py", line 89, in check_error
    raise RuntimeError(error)
RuntimeError: b'CLI : Cannot change this param now'
2024-03-25 10:31:04,315 - ERROR - Get data from plc db error: 'NoneType' object has no attribute 'db_read'
Traceback (most recent call last):
  File "c:\Users\STM\Desktop\Praktik_Eksamensprojekt\Datalogging_Statistics_Project-SystemTM\Snap7_Functions.py", line 41, in get_data_from_plc_db
    data = client.db_read(db_number, index, index+4)
           ^^^^^^^^^^^^^^
AttributeError: 'NoneType' object has no attribute 'db_read'
2024-03-25 10:31:44,074 - ERROR - b'CLI : Cannot change this param now'
2024-03-25 10:31:44,075 - ERROR - Connect snap7 client error: b'CLI : Cannot change this param now'
Traceback (most recent call last):
  File "c:\Users\STM\Desktop\Praktik_Eksamensprojekt\Datalogging_Statistics_Project-SystemTM\Snap7_Functions.py", line 17, in connect_snap7_client
    client.connect(ip_address, rack, slot, tcpport)
  File "C:\Users\STM\AppData\Local\Programs\Python\Python312\Lib\site-packages\snap7\client\__init__.py", line 23, in f
    code = func(*args, **kw)
           ^^^^^^^^^^^^^^^^^
  File "C:\Users\STM\AppData\Local\Programs\Python\Python312\Lib\site-packages\snap7\client\__init__.py", line 192, in connect
    self.set_param(RemotePort, tcpport)
  File "C:\Users\STM\AppData\Local\Programs\Python\Python312\Lib\site-packages\snap7\client\__init__.py", line 24, in f
    check_error(code, context="client")
  File "C:\Users\STM\AppData\Local\Programs\Python\Python312\Lib\site-packages\snap7\common.py", line 89, in check_error
    raise RuntimeError(error)
RuntimeError: b'CLI : Cannot change this param now'
2024-03-25 10:31:44,077 - ERROR - Get data from plc db error: 'NoneType' object has no attribute 'db_read'
Traceback (most recent call last):
  File "c:\Users\STM\Desktop\Praktik_Eksamensprojekt\Datalogging_Statistics_Project-SystemTM\Snap7_Functions.py", line 41, in get_data_from_plc_db
    data = client.db_read(db_number, index, index+4)
           ^^^^^^^^^^^^^^
AttributeError: 'NoneType' object has no attribute 'db_read'
2024-03-25 10:31:49,081 - ERROR - b'CLI : Cannot change this param now'
2024-03-25 10:31:49,081 - ERROR - Connect snap7 client error: b'CLI : Cannot change this param now'
Traceback (most recent call last):
  File "c:\Users\STM\Desktop\Praktik_Eksamensprojekt\Datalogging_Statistics_Project-SystemTM\Snap7_Functions.py", line 17, in connect_snap7_client
    client.connect(ip_address, rack, slot, tcpport)
  File "C:\Users\STM\AppData\Local\Programs\Python\Python312\Lib\site-packages\snap7\client\__init__.py", line 23, in f
    code = func(*args, **kw)
           ^^^^^^^^^^^^^^^^^
  File "C:\Users\STM\AppData\Local\Programs\Python\Python312\Lib\site-packages\snap7\client\__init__.py", line 192, in connect
    self.set_param(RemotePort, tcpport)
  File "C:\Users\STM\AppData\Local\Programs\Python\Python312\Lib\site-packages\snap7\client\__init__.py", line 24, in f
    check_error(code, context="client")
  File "C:\Users\STM\AppData\Local\Programs\Python\Python312\Lib\site-packages\snap7\common.py", line 89, in check_error
    raise RuntimeError(error)
RuntimeError: b'CLI : Cannot change this param now'
2024-03-25 10:31:49,084 - ERROR - Get data from plc db error: 'NoneType' object has no attribute 'db_read'
Traceback (most recent call last):
  File "c:\Users\STM\Desktop\Praktik_Eksamensprojekt\Datalogging_Statistics_Project-SystemTM\Snap7_Functions.py", line 41, in get_data_from_plc_db
    data = client.db_read(db_number, index, index+4)
           ^^^^^^^^^^^^^^
AttributeError: 'NoneType' object has no attribute 'db_read'
2024-03-25 10:35:26,104 - ERROR - b'CLI : Cannot change this param now'
2024-03-25 10:35:26,104 - ERROR - Connect snap7 client error: b'CLI : Cannot change this param now'
Traceback (most recent call last):
  File "c:\Users\STM\Desktop\Praktik_Eksamensprojekt\Datalogging_Statistics_Project-SystemTM\Snap7_Functions.py", line 19, in connect_snap7_client
    client.connect(ip_address, rack, slot, tcpport)
  File "C:\Users\STM\AppData\Local\Programs\Python\Python312\Lib\site-packages\snap7\client\__init__.py", line 23, in f
    code = func(*args, **kw)
           ^^^^^^^^^^^^^^^^^
  File "C:\Users\STM\AppData\Local\Programs\Python\Python312\Lib\site-packages\snap7\client\__init__.py", line 192, in connect
    self.set_param(RemotePort, tcpport)
  File "C:\Users\STM\AppData\Local\Programs\Python\Python312\Lib\site-packages\snap7\client\__init__.py", line 24, in f
    check_error(code, context="client")
  File "C:\Users\STM\AppData\Local\Programs\Python\Python312\Lib\site-packages\snap7\common.py", line 89, in check_error
    raise RuntimeError(error)
RuntimeError: b'CLI : Cannot change this param now'
2024-03-25 10:35:26,106 - ERROR - Get data from plc db error: 'NoneType' object has no attribute 'db_read'
Traceback (most recent call last):
  File "c:\Users\STM\Desktop\Praktik_Eksamensprojekt\Datalogging_Statistics_Project-SystemTM\Snap7_Functions.py", line 43, in get_data_from_plc_db
    data = client.db_read(db_number, index, index+4)
           ^^^^^^^^^^^^^^
AttributeError: 'NoneType' object has no attribute 'db_read'
2024-03-25 10:38:07,119 - ERROR - b'CLI : Cannot change this param now'
2024-03-25 10:38:07,119 - ERROR - Connect snap7 client error: b'CLI : Cannot change this param now'
Traceback (most recent call last):
  File "c:\Users\STM\Desktop\Praktik_Eksamensprojekt\Datalogging_Statistics_Project-SystemTM\Snap7_Functions.py", line 19, in connect_snap7_client
    client.connect(ip_address, rack, slot, tcpport)
  File "C:\Users\STM\AppData\Local\Programs\Python\Python312\Lib\site-packages\snap7\client\__init__.py", line 23, in f
    code = func(*args, **kw)
           ^^^^^^^^^^^^^^^^^
  File "C:\Users\STM\AppData\Local\Programs\Python\Python312\Lib\site-packages\snap7\client\__init__.py", line 192, in connect
    self.set_param(RemotePort, tcpport)
  File "C:\Users\STM\AppData\Local\Programs\Python\Python312\Lib\site-packages\snap7\client\__init__.py", line 24, in f
    check_error(code, context="client")
  File "C:\Users\STM\AppData\Local\Programs\Python\Python312\Lib\site-packages\snap7\common.py", line 89, in check_error
    raise RuntimeError(error)
RuntimeError: b'CLI : Cannot change this param now'
2024-03-25 10:38:07,120 - ERROR - Get data from plc db error: 'NoneType' object has no attribute 'db_read'
Traceback (most recent call last):
  File "c:\Users\STM\Desktop\Praktik_Eksamensprojekt\Datalogging_Statistics_Project-SystemTM\Snap7_Functions.py", line 43, in get_data_from_plc_db
    data = client.db_read(db_number, index, index+4)
           ^^^^^^^^^^^^^^
AttributeError: 'NoneType' object has no attribute 'db_read'
2024-03-25 10:38:12,111 - ERROR - b'CLI : Cannot change this param now'
2024-03-25 10:38:12,112 - ERROR - Connect snap7 client error: b'CLI : Cannot change this param now'
Traceback (most recent call last):
  File "c:\Users\STM\Desktop\Praktik_Eksamensprojekt\Datalogging_Statistics_Project-SystemTM\Snap7_Functions.py", line 19, in connect_snap7_client
    client.connect(ip_address, rack, slot, tcpport)
  File "C:\Users\STM\AppData\Local\Programs\Python\Python312\Lib\site-packages\snap7\client\__init__.py", line 23, in f
    code = func(*args, **kw)
           ^^^^^^^^^^^^^^^^^
  File "C:\Users\STM\AppData\Local\Programs\Python\Python312\Lib\site-packages\snap7\client\__init__.py", line 192, in connect
    self.set_param(RemotePort, tcpport)
  File "C:\Users\STM\AppData\Local\Programs\Python\Python312\Lib\site-packages\snap7\client\__init__.py", line 24, in f
    check_error(code, context="client")
  File "C:\Users\STM\AppData\Local\Programs\Python\Python312\Lib\site-packages\snap7\common.py", line 89, in check_error
    raise RuntimeError(error)
RuntimeError: b'CLI : Cannot change this param now'
2024-03-25 10:38:12,113 - ERROR - Get data from plc db error: 'NoneType' object has no attribute 'db_read'
Traceback (most recent call last):
  File "c:\Users\STM\Desktop\Praktik_Eksamensprojekt\Datalogging_Statistics_Project-SystemTM\Snap7_Functions.py", line 43, in get_data_from_plc_db
    data = client.db_read(db_number, index, index+4)
           ^^^^^^^^^^^^^^
AttributeError: 'NoneType' object has no attribute 'db_read'
2024-03-25 10:39:01,662 - ERROR - b'CLI : Cannot change this param now'
2024-03-25 10:39:01,662 - ERROR - Connect snap7 client error: b'CLI : Cannot change this param now'
Traceback (most recent call last):
  File "c:\Users\STM\Desktop\Praktik_Eksamensprojekt\Datalogging_Statistics_Project-SystemTM\Snap7_Functions.py", line 19, in connect_snap7_client
    client.connect(ip_address, rack, slot, tcpport)
  File "C:\Users\STM\AppData\Local\Programs\Python\Python312\Lib\site-packages\snap7\client\__init__.py", line 23, in f
    code = func(*args, **kw)
           ^^^^^^^^^^^^^^^^^
  File "C:\Users\STM\AppData\Local\Programs\Python\Python312\Lib\site-packages\snap7\client\__init__.py", line 192, in connect
    self.set_param(RemotePort, tcpport)
  File "C:\Users\STM\AppData\Local\Programs\Python\Python312\Lib\site-packages\snap7\client\__init__.py", line 24, in f
    check_error(code, context="client")
  File "C:\Users\STM\AppData\Local\Programs\Python\Python312\Lib\site-packages\snap7\common.py", line 89, in check_error
    raise RuntimeError(error)
RuntimeError: b'CLI : Cannot change this param now'
2024-03-25 10:39:01,665 - ERROR - Get data from plc db error: 'NoneType' object has no attribute 'db_read'
Traceback (most recent call last):
  File "c:\Users\STM\Desktop\Praktik_Eksamensprojekt\Datalogging_Statistics_Project-SystemTM\Snap7_Functions.py", line 43, in get_data_from_plc_db
    data = client.db_read(db_number, index, index+4)
           ^^^^^^^^^^^^^^
AttributeError: 'NoneType' object has no attribute 'db_read'
2024-03-25 10:39:06,671 - ERROR - b'CLI : Cannot change this param now'
2024-03-25 10:39:06,671 - ERROR - Connect snap7 client error: b'CLI : Cannot change this param now'
Traceback (most recent call last):
  File "c:\Users\STM\Desktop\Praktik_Eksamensprojekt\Datalogging_Statistics_Project-SystemTM\Snap7_Functions.py", line 19, in connect_snap7_client
    client.connect(ip_address, rack, slot, tcpport)
  File "C:\Users\STM\AppData\Local\Programs\Python\Python312\Lib\site-packages\snap7\client\__init__.py", line 23, in f
    code = func(*args, **kw)
           ^^^^^^^^^^^^^^^^^
  File "C:\Users\STM\AppData\Local\Programs\Python\Python312\Lib\site-packages\snap7\client\__init__.py", line 192, in connect
    self.set_param(RemotePort, tcpport)
  File "C:\Users\STM\AppData\Local\Programs\Python\Python312\Lib\site-packages\snap7\client\__init__.py", line 24, in f
    check_error(code, context="client")
  File "C:\Users\STM\AppData\Local\Programs\Python\Python312\Lib\site-packages\snap7\common.py", line 89, in check_error
    raise RuntimeError(error)
RuntimeError: b'CLI : Cannot change this param now'
2024-03-25 10:39:06,674 - ERROR - Get data from plc db error: 'NoneType' object has no attribute 'db_read'
Traceback (most recent call last):
  File "c:\Users\STM\Desktop\Praktik_Eksamensprojekt\Datalogging_Statistics_Project-SystemTM\Snap7_Functions.py", line 43, in get_data_from_plc_db
    data = client.db_read(db_number, index, index+4)
           ^^^^^^^^^^^^^^
AttributeError: 'NoneType' object has no attribute 'db_read'
2024-03-25 10:43:07,256 - ERROR - b'CLI : Cannot change this param now'
2024-03-25 10:43:07,256 - ERROR - Connect snap7 client error: b'CLI : Cannot change this param now'
Traceback (most recent call last):
  File "c:\Users\STM\Desktop\Praktik_Eksamensprojekt\Datalogging_Statistics_Project-SystemTM\Snap7_Functions.py", line 19, in connect_snap7_client
    client.connect(ip_address, rack, slot, tcpport)
  File "C:\Users\STM\AppData\Local\Programs\Python\Python312\Lib\site-packages\snap7\client\__init__.py", line 23, in f
    code = func(*args, **kw)
           ^^^^^^^^^^^^^^^^^
  File "C:\Users\STM\AppData\Local\Programs\Python\Python312\Lib\site-packages\snap7\client\__init__.py", line 192, in connect
    self.set_param(RemotePort, tcpport)
  File "C:\Users\STM\AppData\Local\Programs\Python\Python312\Lib\site-packages\snap7\client\__init__.py", line 24, in f
    check_error(code, context="client")
  File "C:\Users\STM\AppData\Local\Programs\Python\Python312\Lib\site-packages\snap7\common.py", line 89, in check_error
    raise RuntimeError(error)
RuntimeError: b'CLI : Cannot change this param now'
2024-03-25 10:43:07,258 - ERROR - Get data from plc db error: 'NoneType' object has no attribute 'db_read'
Traceback (most recent call last):
  File "c:\Users\STM\Desktop\Praktik_Eksamensprojekt\Datalogging_Statistics_Project-SystemTM\Snap7_Functions.py", line 43, in get_data_from_plc_db
    data = client.db_read(db_number, index, index+4)
           ^^^^^^^^^^^^^^
AttributeError: 'NoneType' object has no attribute 'db_read'
2024-03-25 10:43:12,269 - ERROR - b'CLI : Cannot change this param now'
2024-03-25 10:43:12,270 - ERROR - Connect snap7 client error: b'CLI : Cannot change this param now'
Traceback (most recent call last):
  File "c:\Users\STM\Desktop\Praktik_Eksamensprojekt\Datalogging_Statistics_Project-SystemTM\Snap7_Functions.py", line 19, in connect_snap7_client
    client.connect(ip_address, rack, slot, tcpport)
  File "C:\Users\STM\AppData\Local\Programs\Python\Python312\Lib\site-packages\snap7\client\__init__.py", line 23, in f
    code = func(*args, **kw)
           ^^^^^^^^^^^^^^^^^
  File "C:\Users\STM\AppData\Local\Programs\Python\Python312\Lib\site-packages\snap7\client\__init__.py", line 192, in connect
    self.set_param(RemotePort, tcpport)
  File "C:\Users\STM\AppData\Local\Programs\Python\Python312\Lib\site-packages\snap7\client\__init__.py", line 24, in f
    check_error(code, context="client")
  File "C:\Users\STM\AppData\Local\Programs\Python\Python312\Lib\site-packages\snap7\common.py", line 89, in check_error
    raise RuntimeError(error)
RuntimeError: b'CLI : Cannot change this param now'
2024-03-25 10:43:12,272 - ERROR - Get data from plc db error: 'NoneType' object has no attribute 'db_read'
Traceback (most recent call last):
  File "c:\Users\STM\Desktop\Praktik_Eksamensprojekt\Datalogging_Statistics_Project-SystemTM\Snap7_Functions.py", line 43, in get_data_from_plc_db
    data = client.db_read(db_number, index, index+4)
           ^^^^^^^^^^^^^^
AttributeError: 'NoneType' object has no attribute 'db_read'
2024-03-25 15:33:59,055 - ERROR - Write data dbresult error: pack expected 4 items for packing (got 3)
Traceback (most recent call last):
  File "c:\Users\STM\Desktop\Praktik_Eksamensprojekt\Datalogging_Statistics_Project-SystemTM\Snap7_Functions.py", line 137, in write_data_dbresult
    print(format_dtl_bytearray(testtags_db_number, dtl_index))
          ^^^^^^^^^^^^^^^^^^^^^^^^^^^^^^^^^^^^^^^^^^^^^^^^^^^
  File "c:\Users\STM\Desktop\Praktik_Eksamensprojekt\Datalogging_Statistics_Project-SystemTM\Snap7_Functions.py", line 173, in format_dtl_bytearray
    data_fixed = util.get_dint(dtl_bytearray,I+1)
             ^^^^^^^^^^^^^^^^^^^^^^^^^^^^^^^^
  File "C:\Users\STM\AppData\Local\Programs\Python\Python312\Lib\site-packages\snap7\util.py", line 637, in get_dint
    dint = struct.unpack('>i', struct.pack('4B', *data))[0]
                               ^^^^^^^^^^^^^^^^^^^^^^^^
struct.error: pack expected 4 items for packing (got 3)
2024-03-25 15:34:44,173 - ERROR - Write data dbresult error: pack expected 4 items for packing (got 3)
Traceback (most recent call last):
  File "c:\Users\STM\Desktop\Praktik_Eksamensprojekt\Datalogging_Statistics_Project-SystemTM\Snap7_Functions.py", line 137, in write_data_dbresult
    print(format_dtl_bytearray(testtags_db_number, dtl_index))
          ^^^^^^^^^^^^^^^^^^^^^^^^^^^^^^^^^^^^^^^^^^^^^^^^^^^
  File "c:\Users\STM\Desktop\Praktik_Eksamensprojekt\Datalogging_Statistics_Project-SystemTM\Snap7_Functions.py", line 173, in format_dtl_bytearray
    data_fixed = util.get_dint(dtl_bytearray,I+1)
             ^^^^^^^^^^^^^^^^^^^^^^^^^^^^^^^^
  File "C:\Users\STM\AppData\Local\Programs\Python\Python312\Lib\site-packages\snap7\util.py", line 637, in get_dint
    dint = struct.unpack('>i', struct.pack('4B', *data))[0]
                               ^^^^^^^^^^^^^^^^^^^^^^^^
struct.error: pack expected 4 items for packing (got 3)
2024-03-26 08:51:56,467 - ERROR - Write data dbresult error: 'module' object is not callable. Did you mean: 'datetime.datetime(...)'?
Traceback (most recent call last):
  File "c:\Users\STM\Desktop\Praktik_Eksamensprojekt\Datalogging_Statistics_Project-SystemTM\Snap7_Functions.py", line 141, in write_data_dbresult
    dtl_datetime = datetime(year, month, day, hour, minute, second)
                   ^^^^^^^^^^^^^^^^^^^^^^^^^^^^^^^^^^^^^^^^^^^^^^^^
TypeError: 'module' object is not callable. Did you mean: 'datetime.datetime(...)'?
2024-03-26 08:59:23,446 - ERROR - Write data dbresult error: not enough values to unpack (expected 6, got 0)
Traceback (most recent call last):
  File "c:\Users\STM\Desktop\Praktik_Eksamensprojekt\Datalogging_Statistics_Project-SystemTM\Snap7_Functions.py", line 140, in write_data_dbresult
    year, month, day, hour, minute, second = dtl_array[:6]
    ^^^^^^^^^^^^^^^^^^^^^^^^^^^^^^^^^^^^^^
ValueError: not enough values to unpack (expected 6, got 0)
2024-03-26 09:12:49,711 - ERROR - b'CLI : invalid param(s) supplied'
2024-03-26 09:12:49,711 - ERROR - Write data dbresult error: b'CLI : invalid param(s) supplied'
Traceback (most recent call last):
  File "c:\Users\STM\Desktop\Praktik_Eksamensprojekt\Datalogging_Statistics_Project-SystemTM\Snap7_Functions.py", line 162, in write_data_dbresult
    client.db_write(db_number, plc.get('dbresult data index'), bytearray_to_data)
  File "C:\Users\STM\AppData\Local\Programs\Python\Python312\Lib\site-packages\snap7\client\__init__.py", line 24, in f
    check_error(code, context="client")
  File "C:\Users\STM\AppData\Local\Programs\Python\Python312\Lib\site-packages\snap7\common.py", line 89, in check_error
    raise RuntimeError(error)
RuntimeError: b'CLI : invalid param(s) supplied'
2024-03-26 09:13:35,411 - ERROR - b'CLI : invalid param(s) supplied'
2024-03-26 09:13:35,412 - ERROR - Write data dbresult error: b'CLI : invalid param(s) supplied'
Traceback (most recent call last):
  File "c:\Users\STM\Desktop\Praktik_Eksamensprojekt\Datalogging_Statistics_Project-SystemTM\Snap7_Functions.py", line 162, in write_data_dbresult
    client.db_write(db_number, plc.get('dbresult data index'), bytearray_to_data)
  File "C:\Users\STM\AppData\Local\Programs\Python\Python312\Lib\site-packages\snap7\client\__init__.py", line 24, in f
    check_error(code, context="client")
  File "C:\Users\STM\AppData\Local\Programs\Python\Python312\Lib\site-packages\snap7\common.py", line 89, in check_error
    raise RuntimeError(error)
RuntimeError: b'CLI : invalid param(s) supplied'
2024-03-26 09:28:59,848 - ERROR - Write data dbresult error: type object 'datetime.datetime' has no attribute 'datetime'
Traceback (most recent call last):
  File "c:\Users\STM\Desktop\Praktik_Eksamensprojekt\Datalogging_Statistics_Project-SystemTM\Snap7_Functions.py", line 137, in write_data_dbresult
    start_dtl_datetime = get_and_format_dtl_bytearray(testtags_db_number, dtl_index)
                         ^^^^^^^^^^^^^^^^^^^^^^^^^^^^^^^^^^^^^^^^^^^^^^^^^^^^^^^^^^^
  File "c:\Users\STM\Desktop\Praktik_Eksamensprojekt\Datalogging_Statistics_Project-SystemTM\Snap7_Functions.py", line 187, in get_and_format_dtl_bytearray
    dtl_datetime = datetime.datetime(year, month, day, hour, minute, second)
                   ^^^^^^^^^^^^^^^^^
AttributeError: type object 'datetime.datetime' has no attribute 'datetime'
2024-03-26 09:29:21,530 - ERROR - Get log data within range error: 'builtin_function_or_method' object has no attribute 'astimezone'
Traceback (most recent call last):
  File "c:\Users\STM\Desktop\Praktik_Eksamensprojekt\Datalogging_Statistics_Project-SystemTM\SQLiteRead.py", line 140, in get_log_data_within_range
    max_range_utc = max_range.astimezone(pytz.utc)
                    ^^^^^^^^^^^^^^^^^^^^
AttributeError: 'builtin_function_or_method' object has no attribute 'astimezone'
2024-03-26 09:30:03,030 - ERROR - Get log data within range error: 'builtin_function_or_method' object has no attribute 'astimezone'
Traceback (most recent call last):
  File "c:\Users\STM\Desktop\Praktik_Eksamensprojekt\Datalogging_Statistics_Project-SystemTM\SQLiteRead.py", line 140, in get_log_data_within_range
    max_range_utc = max_range.astimezone(pytz.utc)
                    ^^^^^^^^^^^^^^^^^^^^
AttributeError: 'builtin_function_or_method' object has no attribute 'astimezone'
2024-03-26 09:31:21,560 - ERROR - Get log data within range error: 'builtin_function_or_method' object has no attribute 'astimezone'
Traceback (most recent call last):
  File "c:\Users\STM\Desktop\Praktik_Eksamensprojekt\Datalogging_Statistics_Project-SystemTM\SQLiteRead.py", line 141, in get_log_data_within_range
    max_range_utc = max_range.astimezone(pytz.utc)
                    ^^^^^^^^^^^^^^^^^^^^
AttributeError: 'builtin_function_or_method' object has no attribute 'astimezone'
2024-03-26 09:32:05,553 - ERROR - Get log data within range error: 'builtin_function_or_method' object has no attribute 'astimezone'
Traceback (most recent call last):
  File "c:\Users\STM\Desktop\Praktik_Eksamensprojekt\Datalogging_Statistics_Project-SystemTM\SQLiteRead.py", line 141, in get_log_data_within_range
    max_range_utc = max_range.astimezone(pytz.utc)
                    ^^^^^^^^^^^^^^^^^^^^
AttributeError: 'builtin_function_or_method' object has no attribute 'astimezone'
2024-03-26 09:34:07,365 - ERROR - Get log data within range error: 'NoneType' object has no attribute 'astimezone'
Traceback (most recent call last):
  File "c:\Users\STM\Desktop\Praktik_Eksamensprojekt\Datalogging_Statistics_Project-SystemTM\SQLiteRead.py", line 140, in get_log_data_within_range
    max_range_utc = max_range.astimezone(pytz.utc)
                    ^^^^^^^^^^^^^^^^^^^^
AttributeError: 'NoneType' object has no attribute 'astimezone'
